Workbook
Name deepseek_csv_20250903_ef11c1_2: 'ESPN Ranking'!$A$1:$B$401
Name FantasyPros_2025_Draft_ALL_Rankings_7: 'FP Ranking'!$A$1:$J$630

Sheet FF 2025
A1: ="Pick: " & ( COUNTIF( E2:F184, TRUE ) + 1 ) -> Pick: 1 | B1: Round | C1: FP Rank | D1: Player Name | E1: Picked? | F1: By Me? | G1: ESPN Rank | H1: Tier | I1: Team | J1: Position | K1: Difference | L1: Adj Difference | M1: Percentile Adj. Difference
B2: =ROUNDUP( $C2 / 12,0) -> 1 | C2: 1 | D2: =_xlfn.XLOOKUP( C2, 'FP Ranking'!$A$2:$A$544, 'FP Ranking'!$C$2:$C$544 ) -> Ja'Marr Chase | E2: FALSE | F2: FALSE | G2: =_xlfn.XLOOKUP( D2, 'ESPN Ranking'!$B$2:$B$544, 'ESPN Ranking'!$A$2:$A$544 ) -> 1 | H2: =_xlfn.XLOOKUP( C2, 'FP Ranking'!$A$2:$A$544, 'FP Ranking'!$B$2:$B$544 ) -> 1 | I2: =_xlfn.XLOOKUP( C2, 'FP Ranking'!$A$2:$A$544, 'FP Ranking'!$D$2:$D$544 ) -> CIN | J2: {=LEFT(_xlfn.XLOOKUP(C2, 'FP Ranking'!$A$2:$A$544, 'FP Ranking'!$E$2:$E$544), MIN(SEARCH({1,2,3,4,5,6,7,8,9,0}, _xlfn.XLOOKUP(C2, 'FP Ranking'!$A$2:$A$544, 'FP Ranking'!$E$2:$E$544)&{1,2,3,4,5,6,7,8,9,0}))-1)} -> WR | K2: =G2 - C2 -> 0 | L2: =( K2 / -LN( 1 / ( C2^128 + 1 ) ) ) -> 0 | M2: =PERCENTRANK( $L$2:$L$251, L2 ) -> 0.437
B3: =ROUNDUP( $C3 / 12,0) -> 1 | C3: 2 | D3: =_xlfn.XLOOKUP( C3, 'FP Ranking'!$A$2:$A$544, 'FP Ranking'!$C$2:$C$544 ) -> Bijan Robinson | E3: FALSE | F3: FALSE | G3: =_xlfn.XLOOKUP( D3, 'ESPN Ranking'!$B$2:$B$544, 'ESPN Ranking'!$A$2:$A$544 ) -> 2 | H3: =_xlfn.XLOOKUP( C3, 'FP Ranking'!$A$2:$A$544, 'FP Ranking'!$B$2:$B$544 ) -> 1 | I3: =_xlfn.XLOOKUP( C3, 'FP Ranking'!$A$2:$A$544, 'FP Ranking'!$D$2:$D$544 ) -> ATL | J3: {=LEFT(_xlfn.XLOOKUP(C3, 'FP Ranking'!$A$2:$A$544, 'FP Ranking'!$E$2:$E$544), MIN(SEARCH({1,2,3,4,5,6,7,8,9,0}, _xlfn.XLOOKUP(C3, 'FP Ranking'!$A$2:$A$544, 'FP Ranking'!$E$2:$E$544)&{1,2,3,4,5,6,7,8,9,0}))-1)} -> RB | K3: =G3 - C3 -> 0 | L3: =( K3 / -LN( 1 / ( C3^128 + 1 ) ) ) -> 0 | M3: =PERCENTRANK( $L$2:$L$251, L3 ) -> 0.437
B4: =ROUNDUP( $C4 / 12,0) -> 1 | C4: 3 | D4: =_xlfn.XLOOKUP( C4, 'FP Ranking'!$A$2:$A$544, 'FP Ranking'!$C$2:$C$544 ) -> Jahmyr Gibbs | E4: FALSE | F4: FALSE | G4: =_xlfn.XLOOKUP( D4, 'ESPN Ranking'!$B$2:$B$544, 'ESPN Ranking'!$A$2:$A$544 ) -> 5 | H4: =_xlfn.XLOOKUP( C4, 'FP Ranking'!$A$2:$A$544, 'FP Ranking'!$B$2:$B$544 ) -> 1 | I4: =_xlfn.XLOOKUP( C4, 'FP Ranking'!$A$2:$A$544, 'FP Ranking'!$D$2:$D$544 ) -> DET | J4: {=LEFT(_xlfn.XLOOKUP(C4, 'FP Ranking'!$A$2:$A$544, 'FP Ranking'!$E$2:$E$544), MIN(SEARCH({1,2,3,4,5,6,7,8,9,0}, _xlfn.XLOOKUP(C4, 'FP Ranking'!$A$2:$A$544, 'FP Ranking'!$E$2:$E$544)&{1,2,3,4,5,6,7,8,9,0}))-1)} -> RB | K4: =G4 - C4 -> 2 | L4: =( K4 / -LN( 1 / ( C4^128 + 1 ) ) ) -> 0.014222488 | M4: =PERCENTRANK( $L$2:$L$251, L4 ) -> 0.703
B5: =ROUNDUP( $C5 / 12,0) -> 1 | C5: 4 | D5: =_xlfn.XLOOKUP( C5, 'FP Ranking'!$A$2:$A$544, 'FP Ranking'!$C$2:$C$544 ) -> CeeDee Lamb | E5: FALSE | F5: FALSE | G5: =_xlfn.XLOOKUP( D5, 'ESPN Ranking'!$B$2:$B$544, 'ESPN Ranking'!$A$2:$A$544 ) -> 7 | H5: =_xlfn.XLOOKUP( C5, 'FP Ranking'!$A$2:$A$544, 'FP Ranking'!$B$2:$B$544 ) -> 1 | I5: =_xlfn.XLOOKUP( C5, 'FP Ranking'!$A$2:$A$544, 'FP Ranking'!$D$2:$D$544 ) -> DAL | J5: {=LEFT(_xlfn.XLOOKUP(C5, 'FP Ranking'!$A$2:$A$544, 'FP Ranking'!$E$2:$E$544), MIN(SEARCH({1,2,3,4,5,6,7,8,9,0}, _xlfn.XLOOKUP(C5, 'FP Ranking'!$A$2:$A$544, 'FP Ranking'!$E$2:$E$544)&{1,2,3,4,5,6,7,8,9,0}))-1)} -> WR | K5: =G5 - C5 -> 3 | L5: =( K5 / -LN( 1 / ( C5^128 + 1 ) ) ) -> 0.016906583 | M5: =PERCENTRANK( $L$2:$L$251, L5 ) -> 0.733
B6: =ROUNDUP( $C6 / 12,0) -> 1 | C6: 5 | D6: =_xlfn.XLOOKUP( C6, 'FP Ranking'!$A$2:$A$544, 'FP Ranking'!$C$2:$C$544 ) -> Saquon Barkley | E6: FALSE | F6: FALSE | G6: =_xlfn.XLOOKUP( D6, 'ESPN Ranking'!$B$2:$B$544, 'ESPN Ranking'!$A$2:$A$544 ) -> 4 | H6: =_xlfn.XLOOKUP( C6, 'FP Ranking'!$A$2:$A$544, 'FP Ranking'!$B$2:$B$544 ) -> 1 | I6: =_xlfn.XLOOKUP( C6, 'FP Ranking'!$A$2:$A$544, 'FP Ranking'!$D$2:$D$544 ) -> PHI | J6: {=LEFT(_xlfn.XLOOKUP(C6, 'FP Ranking'!$A$2:$A$544, 'FP Ranking'!$E$2:$E$544), MIN(SEARCH({1,2,3,4,5,6,7,8,9,0}, _xlfn.XLOOKUP(C6, 'FP Ranking'!$A$2:$A$544, 'FP Ranking'!$E$2:$E$544)&{1,2,3,4,5,6,7,8,9,0}))-1)} -> RB | K6: =G6 - C6 -> -1 | L6: =( K6 / -LN( 1 / ( C6^128 + 1 ) ) ) -> -0.0048541792 | M6: =PERCENTRANK( $L$2:$L$251, L6 ) -> 0.371
B7: =ROUNDUP( $C7 / 12,0) -> 1 | C7: 6 | D7: =_xlfn.XLOOKUP( C7, 'FP Ranking'!$A$2:$A$544, 'FP Ranking'!$C$2:$C$544 ) -> Justin Jefferson | E7: FALSE | F7: FALSE | G7: =_xlfn.XLOOKUP( D7, 'ESPN Ranking'!$B$2:$B$544, 'ESPN Ranking'!$A$2:$A$544 ) -> 3 | H7: =_xlfn.XLOOKUP( C7, 'FP Ranking'!$A$2:$A$544, 'FP Ranking'!$B$2:$B$544 ) -> 1 | I7: =_xlfn.XLOOKUP( C7, 'FP Ranking'!$A$2:$A$544, 'FP Ranking'!$D$2:$D$544 ) -> MIN | J7: {=LEFT(_xlfn.XLOOKUP(C7, 'FP Ranking'!$A$2:$A$544, 'FP Ranking'!$E$2:$E$544), MIN(SEARCH({1,2,3,4,5,6,7,8,9,0}, _xlfn.XLOOKUP(C7, 'FP Ranking'!$A$2:$A$544, 'FP Ranking'!$E$2:$E$544)&{1,2,3,4,5,6,7,8,9,0}))-1)} -> WR | K7: =G7 - C7 -> -3 | L7: =( K7 / -LN( 1 / ( C7^128 + 1 ) ) ) -> -0.013080718 | M7: =PERCENTRANK( $L$2:$L$251, L7 ) -> 0.211
B8: =ROUNDUP( $C8 / 12,0) -> 1 | C8: 7 | D8: =_xlfn.XLOOKUP( C8, 'FP Ranking'!$A$2:$A$544, 'FP Ranking'!$C$2:$C$544 ) -> Malik Nabers | E8: FALSE | F8: FALSE | G8: =_xlfn.XLOOKUP( D8, 'ESPN Ranking'!$B$2:$B$544, 'ESPN Ranking'!$A$2:$A$544 ) -> 8 | H8: =_xlfn.XLOOKUP( C8, 'FP Ranking'!$A$2:$A$544, 'FP Ranking'!$B$2:$B$544 ) -> 2 | I8: =_xlfn.XLOOKUP( C8, 'FP Ranking'!$A$2:$A$544, 'FP Ranking'!$D$2:$D$544 ) -> NYG | J8: {=LEFT(_xlfn.XLOOKUP(C8, 'FP Ranking'!$A$2:$A$544, 'FP Ranking'!$E$2:$E$544), MIN(SEARCH({1,2,3,4,5,6,7,8,9,0}, _xlfn.XLOOKUP(C8, 'FP Ranking'!$A$2:$A$544, 'FP Ranking'!$E$2:$E$544)&{1,2,3,4,5,6,7,8,9,0}))-1)} -> WR | K8: =G8 - C8 -> 1 | L8: =( K8 / -LN( 1 / ( C8^128 + 1 ) ) ) -> 0.0040148308 | M8: =PERCENTRANK( $L$2:$L$251, L8 ) -> 0.552
B9: =ROUNDUP( $C9 / 12,0) -> 1 | C9: 8 | D9: =_xlfn.XLOOKUP( C9, 'FP Ranking'!$A$2:$A$544, 'FP Ranking'!$C$2:$C$544 ) -> Christian McCaffrey | E9: FALSE | F9: FALSE | G9: =_xlfn.XLOOKUP( D9, 'ESPN Ranking'!$B$2:$B$544, 'ESPN Ranking'!$A$2:$A$544 ) -> 6 | H9: =_xlfn.XLOOKUP( C9, 'FP Ranking'!$A$2:$A$544, 'FP Ranking'!$B$2:$B$544 ) -> 2 | I9: =_xlfn.XLOOKUP( C9, 'FP Ranking'!$A$2:$A$544, 'FP Ranking'!$D$2:$D$544 ) -> SF | J9: {=LEFT(_xlfn.XLOOKUP(C9, 'FP Ranking'!$A$2:$A$544, 'FP Ranking'!$E$2:$E$544), MIN(SEARCH({1,2,3,4,5,6,7,8,9,0}, _xlfn.XLOOKUP(C9, 'FP Ranking'!$A$2:$A$544, 'FP Ranking'!$E$2:$E$544)&{1,2,3,4,5,6,7,8,9,0}))-1)} -> RB | K9: =G9 - C9 -> -2 | L9: =( K9 / -LN( 1 / ( C9^128 + 1 ) ) ) -> -0.0075140367 | M9: =PERCENTRANK( $L$2:$L$251, L9 ) -> 0.311
B10: =ROUNDUP( $C10 / 12,0) -> 1 | C10: 9 | D10: =_xlfn.XLOOKUP( C10, 'FP Ranking'!$A$2:$A$544, 'FP Ranking'!$C$2:$C$544 ) -> Nico Collins | E10: FALSE | F10: FALSE | G10: =_xlfn.XLOOKUP( D10, 'ESPN Ranking'!$B$2:$B$544, 'ESPN Ranking'!$A$2:$A$544 ) -> 13 | H10: =_xlfn.XLOOKUP( C10, 'FP Ranking'!$A$2:$A$544, 'FP Ranking'!$B$2:$B$544 ) -> 2 | I10: =_xlfn.XLOOKUP( C10, 'FP Ranking'!$A$2:$A$544, 'FP Ranking'!$D$2:$D$544 ) -> HOU | J10: {=LEFT(_xlfn.XLOOKUP(C10, 'FP Ranking'!$A$2:$A$544, 'FP Ranking'!$E$2:$E$544), MIN(SEARCH({1,2,3,4,5,6,7,8,9,0}, _xlfn.XLOOKUP(C10, 'FP Ranking'!$A$2:$A$544, 'FP Ranking'!$E$2:$E$544)&{1,2,3,4,5,6,7,8,9,0}))-1)} -> WR | K10: =G10 - C10 -> 4 | L10: =( K10 / -LN( 1 / ( C10^128 + 1 ) ) ) -> 0.014222488 | M10: =PERCENTRANK( $L$2:$L$251, L10 ) -> 0.703
B11: =ROUNDUP( $C11 / 12,0) -> 1 | C11: 10 | D11: =_xlfn.XLOOKUP( C11, 'FP Ranking'!$A$2:$A$544, 'FP Ranking'!$C$2:$C$544 ) -> Amon-Ra St. Brown | E11: FALSE | F11: FALSE | G11: =_xlfn.XLOOKUP( D11, 'ESPN Ranking'!$B$2:$B$544, 'ESPN Ranking'!$A$2:$A$544 ) -> 11 | H11: =_xlfn.XLOOKUP( C11, 'FP Ranking'!$A$2:$A$544, 'FP Ranking'!$B$2:$B$544 ) -> 2 | I11: =_xlfn.XLOOKUP( C11, 'FP Ranking'!$A$2:$A$544, 'FP Ranking'!$D$2:$D$544 ) -> DET | J11: {=LEFT(_xlfn.XLOOKUP(C11, 'FP Ranking'!$A$2:$A$544, 'FP Ranking'!$E$2:$E$544), MIN(SEARCH({1,2,3,4,5,6,7,8,9,0}, _xlfn.XLOOKUP(C11, 'FP Ranking'!$A$2:$A$544, 'FP Ranking'!$E$2:$E$544)&{1,2,3,4,5,6,7,8,9,0}))-1)} -> WR | K11: =G11 - C11 -> 1 | L11: =( K11 / -LN( 1 / ( C11^128 + 1 ) ) ) -> 0.0033929256 | M11: =PERCENTRANK( $L$2:$L$251, L11 ) -> 0.547
B12: =ROUNDUP( $C12 / 12,0) -> 1 | C12: 11 | D12: =_xlfn.XLOOKUP( C12, 'FP Ranking'!$A$2:$A$544, 'FP Ranking'!$C$2:$C$544 ) -> Derrick Henry | E12: FALSE | F12: FALSE | G12: =_xlfn.XLOOKUP( D12, 'ESPN Ranking'!$B$2:$B$544, 'ESPN Ranking'!$A$2:$A$544 ) -> 19 | H12: =_xlfn.XLOOKUP( C12, 'FP Ranking'!$A$2:$A$544, 'FP Ranking'!$B$2:$B$544 ) -> 2 | I12: =_xlfn.XLOOKUP( C12, 'FP Ranking'!$A$2:$A$544, 'FP Ranking'!$D$2:$D$544 ) -> BAL | J12: {=LEFT(_xlfn.XLOOKUP(C12, 'FP Ranking'!$A$2:$A$544, 'FP Ranking'!$E$2:$E$544), MIN(SEARCH({1,2,3,4,5,6,7,8,9,0}, _xlfn.XLOOKUP(C12, 'FP Ranking'!$A$2:$A$544, 'FP Ranking'!$E$2:$E$544)&{1,2,3,4,5,6,7,8,9,0}))-1)} -> RB | K12: =G12 - C12 -> 8 | L12: =( K12 / -LN( 1 / ( C12^128 + 1 ) ) ) -> 0.026064524 | M12: =PERCENTRANK( $L$2:$L$251, L12 ) -> 0.819
B13: =ROUNDUP( $C13 / 12,0) -> 1 | C13: 12 | D13: =_xlfn.XLOOKUP( C13, 'FP Ranking'!$A$2:$A$544, 'FP Ranking'!$C$2:$C$544 ) -> Puka Nacua | E13: FALSE | F13: FALSE | G13: =_xlfn.XLOOKUP( D13, 'ESPN Ranking'!$B$2:$B$544, 'ESPN Ranking'!$A$2:$A$544 ) -> 9 | H13: =_xlfn.XLOOKUP( C13, 'FP Ranking'!$A$2:$A$544, 'FP Ranking'!$B$2:$B$544 ) -> 2 | I13: =_xlfn.XLOOKUP( C13, 'FP Ranking'!$A$2:$A$544, 'FP Ranking'!$D$2:$D$544 ) -> LAR | J13: {=LEFT(_xlfn.XLOOKUP(C13, 'FP Ranking'!$A$2:$A$544, 'FP Ranking'!$E$2:$E$544), MIN(SEARCH({1,2,3,4,5,6,7,8,9,0}, _xlfn.XLOOKUP(C13, 'FP Ranking'!$A$2:$A$544, 'FP Ranking'!$E$2:$E$544)&{1,2,3,4,5,6,7,8,9,0}))-1)} -> WR | K13: =G13 - C13 -> -3 | L13: =( K13 / -LN( 1 / ( C13^128 + 1 ) ) ) -> -0.0094319439 | M13: =PERCENTRANK( $L$2:$L$251, L13 ) -> 0.276
... B201: =ROUNDUP( $C201 / 12,0) -> 17 | C201: 200 | D201: =_xlfn.XLOOKUP( C201, 'FP Ranking'!$A$2:$A$544, 'FP Ranking'!$C$2:$C$544 ) -> Jaylen Wright | E201: FALSE | F201: FALSE | G201: =_xlfn.XLOOKUP( D201, 'ESPN Ranking'!$B$2:$B$544, 'ESPN Ranking'!$A$2:$A$544 ) -> 241 | H201: =_xlfn.XLOOKUP( C201, 'FP Ranking'!$A$2:$A$544, 'FP Ranking'!$B$2:$B$544 ) -> 9 | I201: =_xlfn.XLOOKUP( C201, 'FP Ranking'!$A$2:$A$544, 'FP Ranking'!$D$2:$D$544 ) -> MIA | J201: {=LEFT(_xlfn.XLOOKUP(C201, 'FP Ranking'!$A$2:$A$544, 'FP Ranking'!$E$2:$E$544), MIN(SEARCH({1,2,3,4,5,6,7,8,9,0}, _xlfn.XLOOKUP(C201, 'FP Ranking'!$A$2:$A$544, 'FP Ranking'!$E$2:$E$544)&{1,2,3,4,5,6,7,8,9,0}))-1)} -> RB | K201: =G201 - C201 -> 41 | L201: =( K201 / -LN( 1 / ( C201^128 + 1 ) ) ) -> 0.060455514 | M201: =PERCENTRANK( $L$2:$L$251, L201 ) -> 0.904

Sheet Team
C2: Standard | D2: Round | G2: 2 WR 2 Flex | H2: Round | K2: 3 WR 1 Flex | L2: Round
B3: QB | C3: {=IFERROR( INDEX( 'FF 2025'!$D$2:$D$251, MATCH( 1, ( 'FF 2025'!$F$2:$F$251 = TRUE ) * ( 'FF 2025'!$J$2:$J$251 = "QB" ), 0 ) ), "----" )} -> ---- | D3: =IFERROR( _xlfn.XLOOKUP( C3, 'FF 2025'!$D$2:$D$251, 'FF 2025'!$B$2:$B$251 ), "----" ) -> ---- | F3: QB | G3: {=IFERROR( INDEX( 'FF 2025'!$D$2:$D$251, MATCH( 1, ( 'FF 2025'!$F$2:$F$251 = TRUE ) * ( 'FF 2025'!$J$2:$J$251 = "QB" ), 0 ) ), "----" )} -> ---- | H3: =IFERROR( _xlfn.XLOOKUP( G3, 'FF 2025'!$D$2:$D$251, 'FF 2025'!$B$2:$B$251 ), "----" ) -> ---- | J3: QB | K3: {=IFERROR( INDEX( 'FF 2025'!D2:D$251, MATCH( 1, ( 'FF 2025'!$F$2:$F$251 = TRUE ) * ( 'FF 2025'!$J$2:$J$251 = "QB" ), 0 ) ), "----" )} -> ---- | L3: =IFERROR( _xlfn.XLOOKUP( K3, 'FF 2025'!$D$2:$D$251, 'FF 2025'!$B$2:$B$251 ), "----" ) -> ----
B4: RB | C4: {=IFERROR( INDEX( 'FF 2025'!$D$2:$D$251, SMALL( IF( ( 'FF 2025'!$F$2:$F$251 = TRUE ) * ( 'FF 2025'!$J$2:$J$251 = "RB" ), ROW( 'FF 2025'!$D$2:$D$251 ) - ROW( 'FF 2025'!$D$2 ) + 1 ), 1 ) ), "----" )} -> ---- | D4: =IFERROR( _xlfn.XLOOKUP( C4, 'FF 2025'!$D$2:$D$251, 'FF 2025'!$B$2:$B$251 ), "----" ) -> ---- | F4: RB | G4: {=IFERROR( INDEX( 'FF 2025'!D2:$D$251, SMALL( IF( ( 'FF 2025'!$F$2:$F$251 = TRUE ) * ( 'FF 2025'!$J$2:$J$251 = "RB" ), ROW( 'FF 2025'!D2:$D$251 ) - ROW( 'FF 2025'!$D$2 ) + 1 ), 1 ) ), "----" )} -> ---- | H4: =IFERROR( _xlfn.XLOOKUP( G4, 'FF 2025'!$D$2:$D$251, 'FF 2025'!$B$2:$B$251 ), "----" ) -> ---- | J4: RB | K4: {=IFERROR( INDEX( 'FF 2025'!D2:D$251, SMALL( IF( ( 'FF 2025'!$F$2:$F$251 = TRUE ) * ( 'FF 2025'!$J$2:$J$251 = "RB" ), ROW( 'FF 2025'!$D2:L$251 ) - ROW( 'FF 2025'!$D$2 ) + 1 ), 1 ) ), "----" )} -> ---- | L4: =IFERROR( _xlfn.XLOOKUP( K4, 'FF 2025'!$D$2:$D$251, 'FF 2025'!$B$2:$B$251 ), "----" ) -> ----
B5: RB | C5: {=IFERROR( INDEX( 'FF 2025'!$D$2:$D$251, SMALL( IF( ( 'FF 2025'!$F$2:$F$251 = TRUE ) * ( 'FF 2025'!$J$2:$J$251 = "RB" ), ROW( 'FF 2025'!$D$2:$D$251 ) - ROW( 'FF 2025'!$D$2 ) + 1 ), 2 ) ), "----" )} -> ---- | D5: =IFERROR( _xlfn.XLOOKUP( C5, 'FF 2025'!$D$2:$D$251, 'FF 2025'!$B$2:$B$251 ), "----" ) -> ---- | F5: RB | G5: {=IFERROR( INDEX( 'FF 2025'!D2:$D$251, SMALL( IF( ( 'FF 2025'!$F$2:$F$251 = TRUE ) * ( 'FF 2025'!$J$2:$J$251 = "RB" ), ROW( 'FF 2025'!D2:$D$251 ) - ROW( 'FF 2025'!$D$2 ) + 1 ), 2 ) ), "----" )} -> ---- | H5: =IFERROR( _xlfn.XLOOKUP( G5, 'FF 2025'!$D$2:$D$251, 'FF 2025'!$B$2:$B$251 ), "----" ) -> ---- | J5: RB | K5: {=IFERROR( INDEX( 'FF 2025'!D2:D$251, SMALL( IF( ( 'FF 2025'!$F$2:$F$251 = TRUE ) * ( 'FF 2025'!$J$2:$J$251 = "RB" ), ROW( 'FF 2025'!$D2:L$251 ) - ROW( 'FF 2025'!$D$2 ) + 1 ), 2 ) ), "----" )} -> ---- | L5: =IFERROR( _xlfn.XLOOKUP( K5, 'FF 2025'!$D$2:$D$251, 'FF 2025'!$B$2:$B$251 ), "----" ) -> ----
B6: WR | C6: {=IFERROR( INDEX( 'FF 2025'!$D$2:$D$251, SMALL( IF( ( 'FF 2025'!$F$2:$F$251 = TRUE ) * ( 'FF 2025'!$J$2:$J$251 = "WR" ), ROW( 'FF 2025'!$D$2:$D$251 ) - ROW( 'FF 2025'!$D$2 ) + 1 ), 1 ) ), "----" )} -> ---- | D6: =IFERROR( _xlfn.XLOOKUP( C6, 'FF 2025'!$D$2:$D$251, 'FF 2025'!$B$2:$B$251 ), "----" ) -> ---- | F6: WR | G6: {=IFERROR( INDEX( 'FF 2025'!D2:$D$251, SMALL( IF( ( 'FF 2025'!$F$2:$F$251 = TRUE ) * ( 'FF 2025'!$J$2:$J$251 = "WR" ), ROW( 'FF 2025'!D2:$D$251 ) - ROW( 'FF 2025'!$D$2 ) + 1 ), 1 ) ), "----" )} -> ---- | H6: =IFERROR( _xlfn.XLOOKUP( G6, 'FF 2025'!$D$2:$D$251, 'FF 2025'!$B$2:$B$251 ), "----" ) -> ---- | J6: WR | K6: {=IFERROR( INDEX( 'FF 2025'!D2:D$251, SMALL( IF( ( 'FF 2025'!$F$2:$F$251 = TRUE ) * ( 'FF 2025'!$J$2:$J$251 = "WR" ), ROW( 'FF 2025'!$D2:D$251 ) - ROW( 'FF 2025'!$D$2 ) + 1 ), 1 ) ), "----" )} -> ---- | L6: =IFERROR( _xlfn.XLOOKUP( K6, 'FF 2025'!$D$2:$D$251, 'FF 2025'!$B$2:$B$251 ), "----" ) -> ----
B7: WR | C7: {=IFERROR( INDEX( 'FF 2025'!$D$2:$D$251, SMALL( IF( ( 'FF 2025'!$F$2:$F$251 = TRUE ) * ( 'FF 2025'!$J$2:$J$251 = "WR" ), ROW( 'FF 2025'!$D$2:$D$251) - ROW( 'FF 2025'!$D$2 ) + 1 ), 2 ) ), "----" )} -> ---- | D7: =IFERROR( _xlfn.XLOOKUP( C7, 'FF 2025'!$D$2:$D$251, 'FF 2025'!$B$2:$B$251 ), "----" ) -> ---- | F7: WR | G7: {=IFERROR( INDEX( 'FF 2025'!D2:$D$251, SMALL( IF( ( 'FF 2025'!$F$2:$F$251 = TRUE ) * ( 'FF 2025'!$J$2:$J$251 = "WR" ), ROW( 'FF 2025'!D2:$D$251 ) - ROW( 'FF 2025'!$D$2 ) + 1 ), 2 ) ), "----" )} -> ---- | H7: =IFERROR( _xlfn.XLOOKUP( G7, 'FF 2025'!$D$2:$D$251, 'FF 2025'!$B$2:$B$251 ), "----" ) -> ---- | J7: WR | K7: {=IFERROR( INDEX( 'FF 2025'!D2:D$251, SMALL( IF( ( 'FF 2025'!$F$2:$F$251 = TRUE ) * ( 'FF 2025'!$J$2:$J$251 = "WR" ), ROW( 'FF 2025'!$D2:D$251 ) - ROW( 'FF 2025'!$D$2 ) + 1 ), 2 ) ), "----" )} -> ---- | L7: =IFERROR( _xlfn.XLOOKUP( K7, 'FF 2025'!$D$2:$D$251, 'FF 2025'!$B$2:$B$251 ), "----" ) -> ----
B8: TE | C8: {=IFERROR( INDEX( 'FF 2025'!$D$2:$D$251, MATCH( 1, ( 'FF 2025'!$F$2:$F$251 = TRUE ) * ( 'FF 2025'!$J$2:$J$251 = "TE" ), 0 ) ), "----" )} -> ---- | D8: =IFERROR( _xlfn.XLOOKUP( C8, 'FF 2025'!$D$2:$D$251, 'FF 2025'!$B$2:$B$251 ), "----" ) -> ---- | F8: TE | G8: {=IFERROR( INDEX( 'FF 2025'!D2:$D$251, MATCH( 1, ( 'FF 2025'!$F$2:$F$251 = TRUE ) * ( 'FF 2025'!$J$2:$J$251 = "TE" ), 0 ) ), "----" )} -> ---- | H8: =IFERROR( _xlfn.XLOOKUP( G8, 'FF 2025'!$D$2:$D$251, 'FF 2025'!$B$2:$B$251 ), "----" ) -> ---- | J8: WR | K8: {=IFERROR( INDEX( 'FF 2025'!D2:D$251, SMALL( IF( ( 'FF 2025'!$F$2:$F$251 = TRUE ) * ( 'FF 2025'!$J$2:$J$251 = "WR" ), ROW( 'FF 2025'!$D2:D$251 ) - ROW( 'FF 2025'!$D$2 ) + 1 ), 3 ) ), "----" )} -> ---- | L8: =IFERROR( _xlfn.XLOOKUP( K8, 'FF 2025'!$D$2:$D$251, 'FF 2025'!$B$2:$B$251 ), "----" ) -> ----
B9: Flex | C9: {=IFERROR( INDEX( 'FF 2025'!$D$2:$D$251, SMALL( IF( ( 'FF 2025'!$F$2:$F$251=TRUE ) * ISNUMBER( MATCH( 'FF 2025'!$J$2:$J$251, {"RB","WR","TE"}, 0 ) ) * ISERROR( MATCH( 'FF 2025'!$D$2:$D$251, $C$4:$C$8, 0 ) ), ROW( 'FF 2025'!$D$2:$D$251 ) - ROW( 'FF 2025'!$D$2 ) + 1 ), 1 ) ), "----")} -> ---- | D9: =IFERROR( _xlfn.XLOOKUP( C9, 'FF 2025'!$D$2:$D$251, 'FF 2025'!$B$2:$B$251 ), "----" ) -> ---- | F9: Flex | G9: {=IFERROR( INDEX( 'FF 2025'!D2:$D$251, SMALL( IF( ( 'FF 2025'!$F$2:$F$251=TRUE ) * ISNUMBER( MATCH( 'FF 2025'!$J$2:$J$251, {"RB","WR","TE"}, 0 ) ) * ISERROR( MATCH( 'FF 2025'!D2:$D$251, $G$4:$G$8, 0 ) ), ROW( 'FF 2025'!D2:$D$251 ) - ROW( 'FF 2025'!$D$2 ) + 1 ), 1 ) ), "----")} -> ---- | H9: =IFERROR( _xlfn.XLOOKUP( G9, 'FF 2025'!$D$2:$D$251, 'FF 2025'!$B$2:$B$251 ), "----" ) -> ---- | J9: TE | K9: {=IFERROR( INDEX( 'FF 2025'!D2:D$251, MATCH( 1, ( 'FF 2025'!$F$2:$F$251 = TRUE ) * ( 'FF 2025'!$J$2:$J$251 = "TE" ), 0 ) ), "----" )} -> ---- | L9: =IFERROR( _xlfn.XLOOKUP( K9, 'FF 2025'!$D$2:$D$251, 'FF 2025'!$B$2:$B$251 ), "----" ) -> ----
B10: DST | C10: {=IFERROR( INDEX( 'FF 2025'!$D$2:$D$251, MATCH( 1, ( 'FF 2025'!$F$2:$F$251 = TRUE ) * ( 'FF 2025'!$J$2:$J$251 = "DST" ), 0 ) ), "----" )} -> ---- | D10: =IFERROR( _xlfn.XLOOKUP( C10, 'FF 2025'!$D$2:$D$251, 'FF 2025'!$B$2:$B$251 ), "----" ) -> ---- | F10: Flex | G10: {=IFERROR( INDEX( 'FF 2025'!D2:$D$251, SMALL( IF( ( 'FF 2025'!$F$2:$F$251=TRUE ) * ISNUMBER( MATCH( 'FF 2025'!$J$2:$J$251, {"RB","WR","TE"}, 0 ) ) * ISERROR( MATCH( 'FF 2025'!D2:$D$251, $G$4:$G$9, 0 ) ), ROW( 'FF 2025'!D2:$D$251 ) - ROW( 'FF 2025'!$D$2 ) + 1 ), 1 ) ), "----")} -> ---- | H10: =IFERROR( _xlfn.XLOOKUP( G10, 'FF 2025'!$D$2:$D$251, 'FF 2025'!$B$2:$B$251 ), "----" ) -> ---- | J10: Flex | K10: {=IFERROR( INDEX( 'FF 2025'!D2:$D$251, SMALL( IF( ( 'FF 2025'!$F$2:$F$251=TRUE ) * ISNUMBER( MATCH( 'FF 2025'!$J$2:$J$251, {"RB","WR","TE"}, 0 ) ) * ISERROR( MATCH( 'FF 2025'!D2:D$251, $K$4:$K$9, 0 ) ), ROW( 'FF 2025'!$D2:L$251 ) - ROW( 'FF 2025'!$D$2 ) + 1 ), 1 ) ), "----")} -> ---- | L10: =IFERROR( _xlfn.XLOOKUP( K10, 'FF 2025'!$D$2:$D$251, 'FF 2025'!$B$2:$B$251 ), "----" ) -> ----
B11: K | C11: {=IFERROR( INDEX( 'FF 2025'!$D$2:$D$251, MATCH( 1, ( 'FF 2025'!$F$2:$F$251 = TRUE ) * ( 'FF 2025'!$J$2:$J$251 = "K" ), 0 ) ), "----" )} -> ---- | D11: =IFERROR( _xlfn.XLOOKUP( C11, 'FF 2025'!$D$2:$D$251, 'FF 2025'!$B$2:$B$251 ), "----" ) -> ---- | F11: DST | G11: {=IFERROR( INDEX( 'FF 2025'!D2:$D$251, MATCH( 1, ( 'FF 2025'!$F$2:$F$251 = TRUE ) * ( 'FF 2025'!$J$2:$J$251 = "DST" ), 0 ) ), "----" )} -> ---- | H11: =IFERROR( _xlfn.XLOOKUP( G11, 'FF 2025'!$D$2:$D$251, 'FF 2025'!$B$2:$B$251 ), "----" ) -> ---- | J11: DST | K11: {=IFERROR( INDEX( 'FF 2025'!$D2:D$251, MATCH( 1, ( 'FF 2025'!$F$2:$F$251 = TRUE ) * ( 'FF 2025'!$J$2:$J$251 = "DST" ), 0 ) ), "----" )} -> ---- | L11: =IFERROR( _xlfn.XLOOKUP( K11, 'FF 2025'!$D$2:$D$251, 'FF 2025'!$B$2:$B$251 ), "----" ) -> ----
B12: Bench | C12: {=IFERROR(INDEX('FF 2025'!$D$2:$D$251, SMALL(IF(('FF 2025'!$F$2:$F$251=TRUE)*ISERROR(MATCH('FF 2025'!$D$2:$D$251,$C$3:$C11,0)), ROW('FF 2025'!$D$2:$D$251)-ROW('FF 2025'!$D$2)+1), 1)), "----")} -> ---- | D12: =IFERROR( _xlfn.XLOOKUP( C12, 'FF 2025'!$D$2:$D$251, 'FF 2025'!$B$2:$B$251 ), "----" ) -> ---- | F12: K | G12: {=IFERROR( INDEX( 'FF 2025'!D2:$D$251, MATCH( 1, ( 'FF 2025'!$F$2:$F$251 = TRUE ) * ( 'FF 2025'!$J$2:$J$251 = "K" ), 0 ) ), "----" )} -> ---- | H12: =IFERROR( _xlfn.XLOOKUP( G12, 'FF 2025'!$D$2:$D$251, 'FF 2025'!$B$2:$B$251 ), "----" ) -> ---- | J12: K | K12: {=IFERROR( INDEX( 'FF 2025'!$D2:D$251, MATCH( 1, ( 'FF 2025'!$F$2:$F$251 = TRUE ) * ( 'FF 2025'!$J$2:$J$251 = "K" ), 0 ) ), "----" )} -> ---- | L12: =IFERROR( _xlfn.XLOOKUP( K12, 'FF 2025'!$D$2:$D$251, 'FF 2025'!$B$2:$B$251 ), "----" ) -> ----
B13: Bench | C13: {=IFERROR(INDEX('FF 2025'!$D$2:$D$251, SMALL(IF(('FF 2025'!$F$2:$F$251=TRUE)*ISERROR(MATCH('FF 2025'!$D$2:$D$251,$C$3:$C12,0)), ROW('FF 2025'!$D$2:$D$251)-ROW('FF 2025'!$D$2)+1), 1)), "----")} -> ---- | D13: =IFERROR( _xlfn.XLOOKUP( C13, 'FF 2025'!$D$2:$D$251, 'FF 2025'!$B$2:$B$251 ), "----" ) -> ---- | F13: Bench | G13: {=IFERROR(INDEX('FF 2025'!D2:$D$251, SMALL(IF(('FF 2025'!$F$2:$F$251=TRUE)*ISERROR(MATCH('FF 2025'!D2:$D$251,$G$3:$G$12,0)), ROW('FF 2025'!D2:$D$251)-ROW('FF 2025'!$D$2)+1), 1)), "----")} -> ---- | H13: =IFERROR( _xlfn.XLOOKUP( G13, 'FF 2025'!$D$2:$D$251, 'FF 2025'!$B$2:$B$251 ), "----" ) -> ---- | J13: Bench | K13: {=IFERROR(INDEX('FF 2025'!$D$2:D$251, SMALL(IF(('FF 2025'!$F$2:$F$251=TRUE)*ISERROR(MATCH('FF 2025'!$D$2:D$251,$K$3:$K12,0)), ROW('FF 2025'!$D$2:D$251)-ROW('FF 2025'!$D$2)+1), 1)), "----")} -> ---- | L13: =IFERROR( _xlfn.XLOOKUP( K13, 'FF 2025'!$D$2:$D$251, 'FF 2025'!$B$2:$B$251 ), "----" ) -> ----
B14: Bench | C14: {=IFERROR(INDEX('FF 2025'!$D$2:$D$251, SMALL(IF(('FF 2025'!$F$2:$F$251=TRUE)*ISERROR(MATCH('FF 2025'!$D$2:$D$251,$C$3:$C13,0)), ROW('FF 2025'!$D$2:$D$251)-ROW('FF 2025'!$D$2)+1), 1)), "----")} -> ---- | D14: =IFERROR( _xlfn.XLOOKUP( C14, 'FF 2025'!$D$2:$D$251, 'FF 2025'!$B$2:$B$251 ), "----" ) -> ---- | F14: Bench | G14: {=IFERROR(INDEX('FF 2025'!D2:$D$251, SMALL(IF(('FF 2025'!$F$2:$F$251=TRUE)*ISERROR(MATCH('FF 2025'!D2:$D$251,$G$3:$G$13,0)), ROW('FF 2025'!D2:$D$251)-ROW('FF 2025'!$D$2)+1), 1)), "----")} -> ---- | H14: =IFERROR( _xlfn.XLOOKUP( G14, 'FF 2025'!$D$2:$D$251, 'FF 2025'!$B$2:$B$251 ), "----" ) -> ---- | J14: Bench | K14: {=IFERROR(INDEX('FF 2025'!$D$2:D$251, SMALL(IF(('FF 2025'!$F$2:$F$251=TRUE)*ISERROR(MATCH('FF 2025'!$D$2:D$251,$K$3:$K13,0)), ROW('FF 2025'!$D$2:D$251)-ROW('FF 2025'!$D$2)+1), 1)), "----")} -> ---- | L14: =IFERROR( _xlfn.XLOOKUP( K14, 'FF 2025'!$D$2:$D$251, 'FF 2025'!$B$2:$B$251 ), "----" ) -> ----
B15: Bench | C15: {=IFERROR(INDEX('FF 2025'!$D$2:$D$251, SMALL(IF(('FF 2025'!$F$2:$F$251=TRUE)*ISERROR(MATCH('FF 2025'!$D$2:$D$251,$C$3:$C14,0)), ROW('FF 2025'!$D$2:$D$251)-ROW('FF 2025'!$D$2)+1), 1)), "----")} -> ---- | D15: =IFERROR( _xlfn.XLOOKUP( C15, 'FF 2025'!$D$2:$D$251, 'FF 2025'!$B$2:$B$251 ), "----" ) -> ---- | F15: Bench | G15: {=IFERROR(INDEX('FF 2025'!D2:$D$251, SMALL(IF(('FF 2025'!$F$2:$F$251=TRUE)*ISERROR(MATCH('FF 2025'!D2:$D$251,$G$3:$G$14,0)), ROW('FF 2025'!D2:$D$251)-ROW('FF 2025'!$D$2)+1), 1)), "----")} -> ---- | H15: =IFERROR( _xlfn.XLOOKUP( G15, 'FF 2025'!$D$2:$D$251, 'FF 2025'!$B$2:$B$251 ), "----" ) -> ---- | J15: Bench | K15: {=IFERROR(INDEX('FF 2025'!$D$2:D$251, SMALL(IF(('FF 2025'!$F$2:$F$251=TRUE)*ISERROR(MATCH('FF 2025'!$D$2:D$251,$K$3:$K14,0)), ROW('FF 2025'!$D$2:D$251)-ROW('FF 2025'!$D$2)+1), 1)), "----")} -> ---- | L15: =IFERROR( _xlfn.XLOOKUP( K15, 'FF 2025'!$D$2:$D$251, 'FF 2025'!$B$2:$B$251 ), "----" ) -> ----
B16: Bench | C16: {=IFERROR(INDEX('FF 2025'!$D$2:$D$251, SMALL(IF(('FF 2025'!$F$2:$F$251=TRUE)*ISERROR(MATCH('FF 2025'!$D$2:$D$251,$C$3:$C15,0)), ROW('FF 2025'!$D$2:$D$251)-ROW('FF 2025'!$D$2)+1), 1)), "----")} -> ---- | D16: =IFERROR( _xlfn.XLOOKUP( C16, 'FF 2025'!$D$2:$D$251, 'FF 2025'!$B$2:$B$251 ), "----" ) -> ---- | F16: Bench | G16: {=IFERROR(INDEX('FF 2025'!D2:$D$251, SMALL(IF(('FF 2025'!$F$2:$F$251=TRUE)*ISERROR(MATCH('FF 2025'!D2:$D$251,$G$3:$G$15,0)), ROW('FF 2025'!D2:$D$251)-ROW('FF 2025'!$D$2)+1), 1)), "----")} -> ---- | H16: =IFERROR( _xlfn.XLOOKUP( G16, 'FF 2025'!$D$2:$D$251, 'FF 2025'!$B$2:$B$251 ), "----" ) -> ---- | J16: Bench | K16: {=IFERROR(INDEX('FF 2025'!$D$2:D$251, SMALL(IF(('FF 2025'!$F$2:$F$251=TRUE)*ISERROR(MATCH('FF 2025'!$D$2:D$251,$K$3:$K15,0)), ROW('FF 2025'!$D$2:D$251)-ROW('FF 2025'!$D$2)+1), 1)), "----")} -> ---- | L16: =IFERROR( _xlfn.XLOOKUP( K16, 'FF 2025'!$D$2:$D$251, 'FF 2025'!$B$2:$B$251 ), "----" ) -> ----
B17: Bench | C17: {=IFERROR(INDEX('FF 2025'!$D$2:$D$251, SMALL(IF(('FF 2025'!$F$2:$F$251=TRUE)*ISERROR(MATCH('FF 2025'!$D$2:$D$251,$C$3:$C16,0)), ROW('FF 2025'!$D$2:$D$251)-ROW('FF 2025'!$D$2)+1), 1)), "----")} -> ---- | D17: =IFERROR( _xlfn.XLOOKUP( C17, 'FF 2025'!$D$2:$D$251, 'FF 2025'!$B$2:$B$251 ), "----" ) -> ---- | F17: Bench | G17: {=IFERROR(INDEX('FF 2025'!D2:$D$251, SMALL(IF(('FF 2025'!$F$2:$F$251=TRUE)*ISERROR(MATCH('FF 2025'!D2:$D$251,$G$3:$G$16,0)), ROW('FF 2025'!D2:$D$251)-ROW('FF 2025'!$D$2)+1), 1)), "----")} -> ---- | H17: =IFERROR( _xlfn.XLOOKUP( G17, 'FF 2025'!$D$2:$D$251, 'FF 2025'!$B$2:$B$251 ), "----" ) -> ---- | J17: Bench | K17: {=IFERROR(INDEX('FF 2025'!$D$2:D$251, SMALL(IF(('FF 2025'!$F$2:$F$251=TRUE)*ISERROR(MATCH('FF 2025'!$D$2:D$251,$K$3:$K16,0)), ROW('FF 2025'!$D$2:D$251)-ROW('FF 2025'!$D$2)+1), 1)), "----")} -> ---- | L17: =IFERROR( _xlfn.XLOOKUP( K17, 'FF 2025'!$D$2:$D$251, 'FF 2025'!$B$2:$B$251 ), "----" ) -> ----
F18: Bench | G18: {=IFERROR(INDEX('FF 2025'!D2:$D$251, SMALL(IF(('FF 2025'!$F$2:$F$251=TRUE)*ISERROR(MATCH('FF 2025'!D2:$D$251,$G$3:$G$17,0)), ROW('FF 2025'!D2:$D$251)-ROW('FF 2025'!$D$2)+1), 1)), "----")} -> ---- | H18: =IFERROR( _xlfn.XLOOKUP( G18, 'FF 2025'!$D$2:$D$251, 'FF 2025'!$B$2:$B$251 ), "----" ) -> ---- | J18: Bench | K18: {=IFERROR(INDEX('FF 2025'!$D$2:D$251, SMALL(IF(('FF 2025'!$F$2:$F$251=TRUE)*ISERROR(MATCH('FF 2025'!$D$2:D$251,$K$3:$K17,0)), ROW('FF 2025'!$D$2:D$251)-ROW('FF 2025'!$D$2)+1), 1)), "----")} -> ---- | L18: =IFERROR( _xlfn.XLOOKUP( K18, 'FF 2025'!$D$2:$D$251, 'FF 2025'!$B$2:$B$251 ), "----" ) -> ----

Sheet FP Ranking
A1: RK | B1: TIERS | C1: PLAYER NAME | D1: TEAM | E1: POS | F1: BYE WEEK | G1: UPSIDE | H1: BUST | I1: SOS SEASON | J1: ECR VS. ADP
A2: 1 | B2: 1 | C2: Ja'Marr Chase | D2: CIN | E2: WR1 | F2: 10 | G2: Coach Upside rating | H2: Coach Bust rating | I2: 3 out of 5 stars | J2: 0
A3: 2 | B3: 1 | C3: Bijan Robinson | D3: ATL | E3: RB1 | F3: 5 | G3: Coach Upside rating | H3: Coach Bust rating | I3: 4 out of 5 stars | J3: 0
A4: 3 | B4: 1 | C4: Jahmyr Gibbs | D4: DET | E4: RB2 | F4: 8 | G4: Coach Upside rating | H4: Coach Bust rating | I4: 2 out of 5 stars | J4: 1
A5: 4 | B5: 1 | C5: CeeDee Lamb | D5: DAL | E5: WR2 | F5: 10 | G5: Coach Upside rating | H5: Coach Bust rating | I5: 2 out of 5 stars | J5: 2
A6: 5 | B6: 1 | C6: Saquon Barkley | D6: PHI | E6: RB3 | F6: 9 | G6: Coach Upside rating | H6: Coach Bust rating | I6: 3 out of 5 stars | J6: -2
A7: 6 | B7: 1 | C7: Justin Jefferson | D7: MIN | E7: WR3 | F7: 6 | G7: Coach Upside rating | H7: Coach Bust rating | I7: 2 out of 5 stars | J7: -1
A8: 7 | B8: 2 | C8: Malik Nabers | D8: NYG | E8: WR4 | F8: 14 | G8: Coach Upside rating | H8: Coach Bust rating | I8: 2 out of 5 stars | J8: 4
A9: 8 | B9: 2 | C9: Christian McCaffrey | D9: SF | E9: RB4 | F9: 14 | G9: Coach Upside rating | H9: Coach Bust rating | I9: 3 out of 5 stars | J9: -1
A10: 9 | B10: 2 | C10: Nico Collins | D10: HOU | E10: WR5 | F10: 6 | G10: Coach Upside rating | H10: Coach Bust rating | I10: 4 out of 5 stars | J10: 3
A11: 10 | B11: 2 | C11: Amon-Ra St. Brown | D11: DET | E11: WR6 | F11: 8 | G11: Coach Upside rating | H11: Coach Bust rating | I11: 3 out of 5 stars | J11: -1
A12: 11 | B12: 2 | C12: Derrick Henry | D12: BAL | E12: RB5 | F12: 7 | G12: Coach Upside rating | H12: Coach Bust rating | I12: 3 out of 5 stars | J12: -3
A13: 12 | B13: 2 | C13: Puka Nacua | D13: LAR | E13: WR7 | F13: 8 | G13: Coach Upside rating | H13: Coach Bust rating | I13: 3 out of 5 stars | J13: 2
... A268: 267 | B268: 10 | C268: Kenneth Gainwell | D268: PIT | E268: RB80 | F268: 5 | G268: Coach Upside rating | H268: Coach Bust rating | I268: 3 out of 5 stars | J268: 20
A269: 268 | B269: 10 | C269: Devaughn Vele | D269: NO | E269: WR93 | F269: 11 | G269: Coach Upside rating | H269: Coach Bust rating | I269: 4 out of 5 stars | J269: -
A270: 269 | B270: 10 | C270: Amari Cooper | D270: LV | E270: WR94 | F270: 8 | G270: Coach Upside rating | H270: Coach Bust rating | I270: 4 out of 5 stars | J270: -36
A271: 270 | B271: 10 | C271: Kayshon Boutte | D271: NE | E271: WR95 | F271: 14 | G271: Coach Upside rating | H271: Coach Bust rating | I271: 3 out of 5 stars | J271: 37
A272: 271 | B272: 10 | C272: Anthony Richardson Sr. | D272: IND | E272: QB34 | F272: 11 | G272: Coach Upside rating | H272: Coach Bust rating | I272: 3 out of 5 stars | J272: -28
A273: 272 | B273: 10 | C273: Ty Johnson | D273: BUF | E273: RB81 | F273: 7 | G273: Coach Upside rating | H273: Coach Bust rating | I273: 4 out of 5 stars | J273: 64
A274: 273 | B274: 10 | C274: Elijah Mitchell | D274: KC | E274: RB82 | F274: 10 | G274: Coach Upside rating | H274: Coach Bust rating | I274: 2 out of 5 stars | J274: 17
A275: 274 | B275: 10 | C275: Jalen Tolbert | D275: DAL | E275: WR96 | F275: 10 | G275: Coach Upside rating | H275: Coach Bust rating | I275: 2 out of 5 stars | J275: 60
A276: 275 | B276: 10 | C276: Joshua Karty | D276: LAR | E276: K14 | F276: 8 | G276: Coach Upside rating | H276: Coach Bust rating | I276: 2 out of 5 stars | J276: -23
A277: 276 | B277: 10 | C277: Trevor Etienne | D277: CAR | E277: RB83 | F277: 14 | G277: Coach Upside rating | H277: Coach Bust rating | I277: 4 out of 5 stars | J277: 28
A278: 277 | B278: 10 | C278: Devin Singletary | D278: NYG | E278: RB84 | F278: 14 | G278: Coach Upside rating | H278: Coach Bust rating | I278: 3 out of 5 stars | J278: 16
A279: 278 | B279: 10 | C279: Brandin Cooks | D279: NO | E279: WR97 | F279: 11 | G279: Coach Upside rating | H279: Coach Bust rating | I279: 4 out of 5 stars | J279: 63
A280: 279 | B280: 10 | C280: Antonio Gibson | D280: NE | E280: RB85 | F280: 14 | G280: Coach Upside rating | H280: Coach Bust rating | I280: 4 out of 5 stars | J280: 13
A281: 280 | B281: 11 | C281: Noah Gray | D281: KC | E281: TE34 | F281: 10 | G281: Coach Upside rating | H281: Coach Bust rating | I281: 3 out of 5 stars | J281: 63
A282: 281 | B282: 11 | C282: Nick Westbrook-Ikhine | D282: MIA | E282: WR98 | F282: 12 | G282: Coach Upside rating | H282: Coach Bust rating | I282: 3 out of 5 stars | J282: -
A283: 282 | B283: 11 | C283: Tre Tucker | D283: LV | E283: WR99 | F283: 8 | G283: Coach Upside rating | H283: Coach Bust rating | I283: 4 out of 5 stars | J283: 58
A284: 283 | B284: 11 | C284: Isaiah Davis | D284: NYJ | E284: RB86 | F284: 9 | G284: Coach Upside rating | H284: Coach Bust rating | I284: 5 out of 5 stars | J284: -
A285: 284 | B285: 11 | C285: Elijah Moore | D285: BUF | E285: WR100 | F285: 7 | G285: Coach Upside rating | H285: Coach Bust rating | I285: 3 out of 5 stars | J285: -
A286: 285 | B286: 11 | C286: Jaxson Dart | D286: NYG | E286: QB35 | F286: 14 | G286: Coach Upside rating | H286: Coach Bust rating | I286: 1 out of 5 stars | J286: -51
A287: 286 | B287: 11 | C287: Chicago Bears | D287: CHI | E287: DST17 | F287: 5 | G287: Coach Upside rating‚ÄìNo rating available | H287: Coach Bust rating‚ÄìNo rating available | I287: 2 out of 5 stars | J287: -49
A288: 287 | B288: 11 | C288: Darren Waller | D288: MIA | E288: TE35 | F288: 12 | G288: Coach Upside rating | H288: Coach Bust rating | I288: 3 out of 5 stars | J288: -82
A289: 288 | B289: 11 | C289: Emanuel Wilson | D289: GB | E289: RB87 | F289: 5 | G289: Coach Upside rating | H289: Coach Bust rating | I289: 4 out of 5 stars | J289: 14
A290: 289 | B290: 11 | C290: Jalen Nailor | D290: MIN | E290: WR101 | F290: 6 | G290: Coach Upside rating‚ÄìNo rating available | H290: Coach Bust rating‚ÄìNo rating available | I290: 2 out of 5 stars | J290: -
A291: 290 | B291: 11 | C291: Dallas Cowboys | D291: DAL | E291: DST18 | F291: 10 | G291: Coach Upside rating‚ÄìNo rating available | H291: Coach Bust rating‚ÄìNo rating available | I291: 0 out of 5 stars | J291: -49
A292: 291 | B292: 11 | C292: Parker Washington | D292: JAC | E292: WR102 | F292: 8 | G292: Coach Upside rating | H292: Coach Bust rating | I292: 4 out of 5 stars | J292: -
A293: 292 | B293: 11 | C293: Tyler Loop | D293: BAL | E293: K15 | F293: 7 | G293: Coach Upside rating | H293: Coach Bust rating | I293: 2 out of 5 stars | J293: -95
A294: 293 | B294: 11 | C294: Chris Brooks | D294: GB | E294: RB88 | F294: 5 | G294: Coach Upside rating | H294: Coach Bust rating | I294: 4 out of 5 stars | J294: -
...

Sheet ESPN Ranking
A1: RANK | B1: PLAYER
A2: 1 | B2: Ja'Marr Chase
A3: 2 | B3: Bijan Robinson
A4: 3 | B4: Justin Jefferson
A5: 4 | B5: Saquon Barkley
A6: 5 | B6: Jahmyr Gibbs
A7: 6 | B7: Christian McCaffrey
A8: 7 | B8: CeeDee Lamb
A9: 8 | B9: Malik Nabers
A10: 9 | B10: Puka Nacua
A11: 10 | B11: Ashton Jeanty
A12: 11 | B12: Amon-Ra St. Brown
A13: 12 | B13: De'Von Achane
... A401: 400 | B401: Sterling Shepard
