Workbook

Sheet MM 2025
D1: Win Round of 64 | H1: Win Round of 32 | L1: Win Sweet Sixteen | P1: Win Elite Eight | T1: Win Final Four | X1: Win National Championship
A2: Team | B2: Seed | C2: Region | D2: Odds | E2: WPW | F2: Gain | G2: Adj Gain | H2: Odds | I2: WPW | J2: Gain | K2: Adj Gain | L2: Odds | M2: WPW | N2: Gain | O2: Adj Gain | P2: Odds | Q2: WPW | R2: Gain | S2: Adj Gain | T2: Odds | U2: WPW | V2: Gain | W2: Adj Gain | X2: Odds | Y2: WPW | Z2: Gain | AA2: Adj Gain
A3: Houston | B3: 1 | C3: Midwest | D3: =VLOOKUP(A3,Odds!A18:I18,4,FALSE) -> 0.9799 | E3: =VLOOKUP(A3,'Yahoo WPW'!A18:I18,4,FALSE) -> 0.9567 | F3: =D3-E3 -> 0.0232 | G3: =F3*D3 -> 0.02273368 | H3: =VLOOKUP(A3,Odds!A18:I18,5,FALSE) -> 0.74962 | I3: =VLOOKUP(A3,'Yahoo WPW'!A18:I18,5,FALSE) -> 0.7871 | J3: =H3-I3 -> -0.03748 | K3: =J3*H3 -> -0.028095758 | L3: =VLOOKUP(A3,Odds!A18:I18,6,FALSE) -> 0.59315 | M3: =VLOOKUP(A3,'Yahoo WPW'!A18:I18,6,FALSE) -> 0.6655 | N3: =L3-M3 -> -0.07235 | O3: =N3*L3 -> -0.042914403 | P3: =VLOOKUP(A3,Odds!A18:I18,7,FALSE) -> 0.43931 | Q3: =VLOOKUP(A3,'Yahoo WPW'!A18:I18,7,FALSE) -> 0.442 | R3: =P3-Q3 -> -0.00269 | S3: =R3*P3 -> -0.0011817439 | T3: =VLOOKUP(A3,Odds!A18:I18,8,FALSE) -> 0.28408 | U3: =VLOOKUP(A3,'Yahoo WPW'!A18:I18,8,FALSE) -> 0.1647 | V3: =T3-U3 -> 0.11938 | W3: =V3*T3 -> 0.03391347 | X3: =VLOOKUP(A3,Odds!A18:I18,9,FALSE) -> 0.17323 | Y3: =VLOOKUP(A3,'Yahoo WPW'!A18:I18,9,FALSE) -> 0.0846 | Z3: =X3-Y3 -> 0.08863 | AA3: =Z3*X3 -> 0.015353375
A4: St. John's | B4: 2 | C4: West | D4: =VLOOKUP(A4,Odds!A51:I51,4,FALSE) -> 0.94015 | E4: =VLOOKUP(A4,'Yahoo WPW'!A51:I51,4,FALSE) -> 0.939 | F4: =D4-E4 -> 0.00115 | G4: =F4*D4 -> 0.0010811725 | H4: =VLOOKUP(A4,Odds!A51:I51,5,FALSE) -> 0.74754 | I4: =VLOOKUP(A4,'Yahoo WPW'!A51:I51,5,FALSE) -> 0.6753 | J4: =H4-I4 -> 0.07224 | K4: =J4*H4 -> 0.05400229 | L4: =VLOOKUP(A4,Odds!A51:I51,6,FALSE) -> 0.51627 | M4: =VLOOKUP(A4,'Yahoo WPW'!A51:I51,6,FALSE) -> 0.4925 | N4: =L4-M4 -> 0.02377 | O4: =N4*L4 -> 0.012271738 | P4: =VLOOKUP(A4,Odds!A51:I51,7,FALSE) -> 0.2637 | Q4: =VLOOKUP(A4,'Yahoo WPW'!A51:I51,7,FALSE) -> 0.2019 | R4: =P4-Q4 -> 0.0618 | S4: =R4*P4 -> 0.01629666 | T4: =VLOOKUP(A4,Odds!A51:I51,8,FALSE) -> 0.15608 | U4: =VLOOKUP(A4,'Yahoo WPW'!A51:I51,8,FALSE) -> 0.1133 | V4: =T4-U4 -> 0.04278 | W4: =V4*T4 -> 0.0066771024 | X4: =VLOOKUP(A4,Odds!A51:I51,9,FALSE) -> 0.08061 | Y4: =VLOOKUP(A4,'Yahoo WPW'!A51:I51,9,FALSE) -> 0.0507 | Z4: =X4-Y4 -> 0.02991 | AA4: =Z4*X4 -> 0.0024110451
A5: Michigan State | B5: 2 | C5: South | D5: =VLOOKUP(A5,Odds!A35:I35,4,FALSE) -> 0.91903 | E5: =VLOOKUP(A5,'Yahoo WPW'!A35:I35,4,FALSE) -> 0.9587 | F5: =D5-E5 -> -0.03967 | G5: =F5*D5 -> -0.03645792 | H5: =VLOOKUP(A5,Odds!A35:I35,5,FALSE) -> 0.6532 | I5: =VLOOKUP(A5,'Yahoo WPW'!A35:I35,5,FALSE) -> 0.7921 | J5: =H5-I5 -> -0.1389 | K5: =J5*H5 -> -0.09072948 | L5: =VLOOKUP(A5,Odds!A35:I35,6,FALSE) -> 0.45616 | M5: =VLOOKUP(A5,'Yahoo WPW'!A35:I35,6,FALSE) -> 0.587 | N5: =L5-M5 -> -0.13084 | O5: =N5*L5 -> -0.059683974 | P5: =VLOOKUP(A5,Odds!A35:I35,7,FALSE) -> 0.25885 | Q5: =VLOOKUP(A5,'Yahoo WPW'!A35:I35,7,FALSE) -> 0.2518 | R5: =P5-Q5 -> 0.00705 | S5: =R5*P5 -> 0.0018248925 | T5: =VLOOKUP(A5,Odds!A35:I35,8,FALSE) -> 0.12615 | U5: =VLOOKUP(A5,'Yahoo WPW'!A35:I35,8,FALSE) -> 0.1037 | V5: =T5-U5 -> 0.02245 | W5: =V5*T5 -> 0.0028320675 | X5: =VLOOKUP(A5,Odds!A35:I35,9,FALSE) -> 0.062 | Y5: =VLOOKUP(A5,'Yahoo WPW'!A35:I35,9,FALSE) -> 0.0436 | Z5: =X5-Y5 -> 0.0184 | AA5: =Z5*X5 -> 0.0011408
A6: Tennessee | B6: 2 | C6: Midwest | D6: =VLOOKUP(A6,Odds!A19:I19,4,FALSE) -> 0.91219 | E6: =VLOOKUP(A6,'Yahoo WPW'!A19:I19,4,FALSE) -> 0.9417 | F6: =D6-E6 -> -0.02951 | G6: =F6*D6 -> -0.026918727 | H6: =VLOOKUP(A6,Odds!A19:I19,5,FALSE) -> 0.69661 | I6: =VLOOKUP(A6,'Yahoo WPW'!A19:I19,5,FALSE) -> 0.7791 | J6: =H6-I6 -> -0.08249 | K6: =J6*H6 -> -0.057463359 | L6: =VLOOKUP(A6,Odds!A19:I19,6,FALSE) -> 0.49933 | M6: =VLOOKUP(A6,'Yahoo WPW'!A19:I19,6,FALSE) -> 0.5511 | N6: =L6-M6 -> -0.05177 | O6: =N6*L6 -> -0.025850314 | P6: =VLOOKUP(A6,Odds!A19:I19,7,FALSE) -> 0.2314 | Q6: =VLOOKUP(A6,'Yahoo WPW'!A19:I19,7,FALSE) -> 0.2512 | R6: =P6-Q6 -> -0.0198 | S6: =R6*P6 -> -0.00458172 | T6: =VLOOKUP(A6,Odds!A19:I19,8,FALSE) -> 0.11594 | U6: =VLOOKUP(A6,'Yahoo WPW'!A19:I19,8,FALSE) -> 0.0826 | V6: =T6-U6 -> 0.03334 | W6: =V6*T6 -> 0.0038654396 | X6: =VLOOKUP(A6,Odds!A19:I19,9,FALSE) -> 0.05392 | Y6: =VLOOKUP(A6,'Yahoo WPW'!A19:I19,9,FALSE) -> 0.0336 | Z6: =X6-Y6 -> 0.02032 | AA6: =Z6*X6 -> 0.0010956544
A7: Maryland | B7: 4 | C7: West | D7: =VLOOKUP(A7,Odds!A53:I53,4,FALSE) -> 0.82263 | E7: =VLOOKUP(A7,'Yahoo WPW'!A53:I53,4,FALSE) -> 0.8389 | F7: =D7-E7 -> -0.01627 | G7: =F7*D7 -> -0.01338419 | H7: =VLOOKUP(A7,Odds!A53:I53,5,FALSE) -> 0.55417 | I7: =VLOOKUP(A7,'Yahoo WPW'!A53:I53,5,FALSE) -> 0.5268 | J7: =H7-I7 -> 0.02737 | K7: =J7*H7 -> 0.015167633 | L7: =VLOOKUP(A7,Odds!A53:I53,6,FALSE) -> 0.2126 | M7: =VLOOKUP(A7,'Yahoo WPW'!A53:I53,6,FALSE) -> 0.0964 | N7: =L7-M7 -> 0.1162 | O7: =N7*L7 -> 0.02470412 | P7: =VLOOKUP(A7,Odds!A53:I53,7,FALSE) -> 0.10691 | Q7: =VLOOKUP(A7,'Yahoo WPW'!A53:I53,7,FALSE) -> 0.0449 | R7: =P7-Q7 -> 0.06201 | S7: =R7*P7 -> 0.0066294891 | T7: =VLOOKUP(A7,Odds!A53:I53,8,FALSE) -> 0.05306 | U7: =VLOOKUP(A7,'Yahoo WPW'!A53:I53,8,FALSE) -> 0.017 | V7: =T7-U7 -> 0.03606 | W7: =V7*T7 -> 0.0019133436 | X7: =VLOOKUP(A7,Odds!A53:I53,9,FALSE) -> 0.02296 | Y7: =VLOOKUP(A7,'Yahoo WPW'!A53:I53,9,FALSE) -> 0.0069 | Z7: =X7-Y7 -> 0.01606 | AA7: =Z7*X7 -> 0.0003687376
A8: Texas Tech | B8: 3 | C8: West | D8: =VLOOKUP(A8,Odds!A52:I52,4,FALSE) -> 0.86205 | E8: =VLOOKUP(A8,'Yahoo WPW'!A52:I52,4,FALSE) -> 0.9139 | F8: =D8-E8 -> -0.05185 | G8: =F8*D8 -> -0.044697293 | H8: =VLOOKUP(A8,Odds!A52:I52,5,FALSE) -> 0.5701 | I8: =VLOOKUP(A8,'Yahoo WPW'!A52:I52,5,FALSE) -> 0.6144 | J8: =H8-I8 -> -0.0443 | K8: =J8*H8 -> -0.02525543 | L8: =VLOOKUP(A8,Odds!A52:I52,6,FALSE) -> 0.26292 | M8: =VLOOKUP(A8,'Yahoo WPW'!A52:I52,6,FALSE) -> 0.2406 | N8: =L8-M8 -> 0.02232 | O8: =N8*L8 -> 0.0058683744 | P8: =VLOOKUP(A8,Odds!A52:I52,7,FALSE) -> 0.1027 | Q8: =VLOOKUP(A8,'Yahoo WPW'!A52:I52,7,FALSE) -> 0.0699 | R8: =P8-Q8 -> 0.0328 | S8: =R8*P8 -> 0.00336856 | T8: =VLOOKUP(A8,Odds!A52:I52,8,FALSE) -> 0.04804 | U8: =VLOOKUP(A8,'Yahoo WPW'!A52:I52,8,FALSE) -> 0.0247 | V8: =T8-U8 -> 0.02334 | W8: =V8*T8 -> 0.0011212536 | X8: =VLOOKUP(A8,Odds!A52:I52,9,FALSE) -> 0.01993 | Y8: =VLOOKUP(A8,'Yahoo WPW'!A52:I52,9,FALSE) -> 0.0074 | Z8: =X8-Y8 -> 0.01253 | AA8: =Z8*X8 -> 0.0002497229
A9: Arizona | B9: 4 | C9: East | D9: =VLOOKUP(A9,Odds!A5:I5,4,FALSE) -> 0.85792 | E9: =VLOOKUP(A9,'Yahoo WPW'!A5:I5,4,FALSE) -> 0.8519 | F9: =D9-E9 -> 0.00602 | G9: =F9*D9 -> 0.0051646784 | H9: =VLOOKUP(A9,Odds!A5:I5,5,FALSE) -> 0.56799 | I9: =VLOOKUP(A9,'Yahoo WPW'!A5:I5,5,FALSE) -> 0.5201 | J9: =H9-I9 -> 0.04789 | K9: =J9*H9 -> 0.027201041 | L9: =VLOOKUP(A9,Odds!A5:I5,6,FALSE) -> 0.20823 | M9: =VLOOKUP(A9,'Yahoo WPW'!A5:I5,6,FALSE) -> 0.0898 | N9: =L9-M9 -> 0.11843 | O9: =N9*L9 -> 0.024660679 | P9: =VLOOKUP(A9,Odds!A5:I5,7,FALSE) -> 0.10611 | Q9: =VLOOKUP(A9,'Yahoo WPW'!A5:I5,7,FALSE) -> 0.0394 | R9: =P9-Q9 -> 0.06671 | S9: =R9*P9 -> 0.0070785981 | T9: =VLOOKUP(A9,Odds!A5:I5,8,FALSE) -> 0.04294 | U9: =VLOOKUP(A9,'Yahoo WPW'!A5:I5,8,FALSE) -> 0.0162 | V9: =T9-U9 -> 0.02674 | W9: =V9*T9 -> 0.0011482156 | X9: =VLOOKUP(A9,Odds!A5:I5,9,FALSE) -> 0.01627 | Y9: =VLOOKUP(A9,'Yahoo WPW'!A5:I5,9,FALSE) -> 0.0075 | Z9: =X9-Y9 -> 0.00877 | AA9: =Z9*X9 -> 0.0001426879
A10: Alabama | B10: 2 | C10: East | D10: =VLOOKUP(A10,Odds!A3:I3,4,FALSE) -> 0.90309 | E10: =VLOOKUP(A10,'Yahoo WPW'!A3:I3,4,FALSE) -> 0.946 | F10: =D10-E10 -> -0.04291 | G10: =F10*D10 -> -0.038751592 | H10: =VLOOKUP(A10,Odds!A3:I3,5,FALSE) -> 0.59839 | I10: =VLOOKUP(A10,'Yahoo WPW'!A3:I3,5,FALSE) -> 0.7902 | J10: =H10-I10 -> -0.19181 | K10: =J10*H10 -> -0.11477719 | L10: =VLOOKUP(A10,Odds!A3:I3,6,FALSE) -> 0.37175 | M10: =VLOOKUP(A10,'Yahoo WPW'!A3:I3,6,FALSE) -> 0.5595 | N10: =L10-M10 -> -0.18775 | O10: =N10*L10 -> -0.069796062 | P10: =VLOOKUP(A10,Odds!A3:I3,7,FALSE) -> 0.17502 | Q10: =VLOOKUP(A10,'Yahoo WPW'!A3:I3,7,FALSE) -> 0.179 | R10: =P10-Q10 -> -0.00398 | S10: =R10*P10 -> -0.0006965796 | T10: =VLOOKUP(A10,Odds!A3:I3,8,FALSE) -> 0.08215 | U10: =VLOOKUP(A10,'Yahoo WPW'!A3:I3,8,FALSE) -> 0.0848 | V10: =T10-U10 -> -0.00265 | W10: =V10*T10 -> -0.0002176975 | X10: =VLOOKUP(A10,Odds!A3:I3,9,FALSE) -> 0.03663 | Y10: =VLOOKUP(A10,'Yahoo WPW'!A3:I3,9,FALSE) -> 0.0332 | Z10: =X10-Y10 -> 0.00343 | AA10: =Z10*X10 -> 0.0001256409
A11: Clemson | B11: 5 | C11: Midwest | D11: =VLOOKUP(A11,Odds!A22:I22,4,FALSE) -> 0.81641 | E11: =VLOOKUP(A11,'Yahoo WPW'!A22:I22,4,FALSE) -> 0.8242 | F11: =D11-E11 -> -0.00779 | G11: =F11*D11 -> -0.0063598339 | H11: =VLOOKUP(A11,Odds!A22:I22,5,FALSE) -> 0.55399 | I11: =VLOOKUP(A11,'Yahoo WPW'!A22:I22,5,FALSE) -> 0.4862 | J11: =H11-I11 -> 0.06779 | K11: =J11*H11 -> 0.037554982 | L11: =VLOOKUP(A11,Odds!A22:I22,6,FALSE) -> 0.18048 | M11: =VLOOKUP(A11,'Yahoo WPW'!A22:I22,6,FALSE) -> 0.1045 | N11: =L11-M11 -> 0.07598 | O11: =N11*L11 -> 0.01371287 | P11: =VLOOKUP(A11,Odds!A22:I22,7,FALSE) -> 0.09307 | Q11: =VLOOKUP(A11,'Yahoo WPW'!A22:I22,7,FALSE) -> 0.039 | R11: =P11-Q11 -> 0.05407 | S11: =R11*P11 -> 0.0050322949 | T11: =VLOOKUP(A11,Odds!A22:I22,8,FALSE) -> 0.03766 | U11: =VLOOKUP(A11,'Yahoo WPW'!A22:I22,8,FALSE) -> 0.0111 | V11: =T11-U11 -> 0.02656 | W11: =V11*T11 -> 0.0010002496 | X11: =VLOOKUP(A11,Odds!A22:I22,9,FALSE) -> 0.01338 | Y11: =VLOOKUP(A11,'Yahoo WPW'!A22:I22,9,FALSE) -> 0.0041 | Z11: =X11-Y11 -> 0.00928 | AA11: =Z11*X11 -> 0.0001241664
A12: Saint Mary's | B12: 7 | C12: East | D12: =VLOOKUP(A12,Odds!A8:I8,4,FALSE) -> 0.77832 | E12: =VLOOKUP(A12,'Yahoo WPW'!A8:I8,4,FALSE) -> 0.5526 | F12: =D12-E12 -> 0.22572 | G12: =F12*D12 -> 0.17568239 | H12: =VLOOKUP(A12,Odds!A8:I8,5,FALSE) -> 0.33945 | I12: =VLOOKUP(A12,'Yahoo WPW'!A8:I8,5,FALSE) -> 0.1222 | J12: =H12-I12 -> 0.21725 | K12: =J12*H12 -> 0.073745512 | L12: =VLOOKUP(A12,Odds!A8:I8,6,FALSE) -> 0.17386 | M12: =VLOOKUP(A12,'Yahoo WPW'!A8:I8,6,FALSE) -> 0.037 | N12: =L12-M12 -> 0.13686 | O12: =N12*L12 -> 0.02379448 | P12: =VLOOKUP(A12,Odds!A8:I8,7,FALSE) -> 0.06482 | Q12: =VLOOKUP(A12,'Yahoo WPW'!A8:I8,7,FALSE) -> 0.0071 | R12: =P12-Q12 -> 0.05772 | S12: =R12*P12 -> 0.0037414104 | T12: =VLOOKUP(A12,Odds!A8:I8,8,FALSE) -> 0.02439 | U12: =VLOOKUP(A12,'Yahoo WPW'!A8:I8,8,FALSE) -> 0.0025 | V12: =T12-U12 -> 0.02189 | W12: =V12*T12 -> 0.0005338971 | X12: =VLOOKUP(A12,Odds!A8:I8,9,FALSE) -> 0.00867 | Y12: =VLOOKUP(A12,'Yahoo WPW'!A8:I8,9,FALSE) -> 0.001 | Z12: =X12-Y12 -> 0.00767 | AA12: =Z12*X12 -> 6.64989e-05
A13: Gonzaga | B13: 8 | C13: Midwest | D13: =VLOOKUP(A13,Odds!A25:I25,4,FALSE) -> 0.68314 | E13: =VLOOKUP(A13,'Yahoo WPW'!A25:I25,4,FALSE) -> 0.6918 | F13: =D13-E13 -> -0.00866 | G13: =F13*D13 -> -0.0059159924 | H13: =VLOOKUP(A13,Odds!A25:I25,5,FALSE) -> 0.19738 | I13: =VLOOKUP(A13,'Yahoo WPW'!A25:I25,5,FALSE) -> 0.1296 | J13: =H13-I13 -> 0.06778 | K13: =J13*H13 -> 0.013378416 | L13: =VLOOKUP(A13,Odds!A25:I25,6,FALSE) -> 0.11934 | M13: =VLOOKUP(A13,'Yahoo WPW'!A25:I25,6,FALSE) -> 0.0732 | N13: =L13-M13 -> 0.04614 | O13: =N13*L13 -> 0.0055063476 | P13: =VLOOKUP(A13,Odds!A25:I25,7,FALSE) -> 0.06348 | Q13: =VLOOKUP(A13,'Yahoo WPW'!A25:I25,7,FALSE) -> 0.0317 | R13: =P13-Q13 -> 0.03178 | S13: =R13*P13 -> 0.0020173944 | T13: =VLOOKUP(A13,Odds!A25:I25,8,FALSE) -> 0.02699 | U13: =VLOOKUP(A13,'Yahoo WPW'!A25:I25,8,FALSE) -> 0.0112 | V13: =T13-U13 -> 0.01579 | W13: =V13*T13 -> 0.0004261721 | X13: =VLOOKUP(A13,Odds!A25:I25,9,FALSE) -> 0.01039 | Y13: =VLOOKUP(A13,'Yahoo WPW'!A25:I25,9,FALSE) -> 0.006 | Z13: =X13-Y13 -> 0.00439 | AA13: =Z13*X13 -> 4.56121e-05
A14: Iowa State | B14: 3 | C14: South | D14: =VLOOKUP(A14,Odds!A36:I36,4,FALSE) -> 0.83568 | E14: =VLOOKUP(A14,'Yahoo WPW'!A36:I36,4,FALSE) -> 0.9287 | F14: =D14-E14 -> -0.09302 | G14: =F14*D14 -> -0.077734954 | H14: =VLOOKUP(A14,Odds!A36:I36,5,FALSE) -> 0.48611 | I14: =VLOOKUP(A14,'Yahoo WPW'!A36:I36,5,FALSE) -> 0.6363 | J14: =H14-I14 -> -0.15019 | K14: =J14*H14 -> -0.073008861 | L14: =VLOOKUP(A14,Odds!A36:I36,6,FALSE) -> 0.2055 | M14: =VLOOKUP(A14,'Yahoo WPW'!A36:I36,6,FALSE) -> 0.2221 | N14: =L14-M14 -> -0.0166 | O14: =N14*L14 -> -0.0034113 | P14: =VLOOKUP(A14,Odds!A36:I36,7,FALSE) -> 0.0859 | Q14: =VLOOKUP(A14,'Yahoo WPW'!A36:I36,7,FALSE) -> 0.0641 | R14: =P14-Q14 -> 0.0218 | S14: =R14*P14 -> 0.00187262 | T14: =VLOOKUP(A14,Odds!A36:I36,8,FALSE) -> 0.02877 | U14: =VLOOKUP(A14,'Yahoo WPW'!A36:I36,8,FALSE) -> 0.0223 | V14: =T14-U14 -> 0.00647 | W14: =V14*T14 -> 0.0001861419 | X14: =VLOOKUP(A14,Odds!A36:I36,9,FALSE) -> 0.00995 | Y14: =VLOOKUP(A14,'Yahoo WPW'!A36:I36,9,FALSE) -> 0.0064 | Z14: =X14-Y14 -> 0.00355 | AA14: =Z14*X14 -> 3.53225e-05
A15: Louisville | B15: 8 | C15: South | D15: =VLOOKUP(A15,Odds!A41:I41,4,FALSE) -> 0.57263 | E15: =VLOOKUP(A15,'Yahoo WPW'!A41:I41,4,FALSE) -> 0.5445 | F15: =D15-E15 -> 0.02813 | G15: =F15*D15 -> 0.016108082 | H15: =VLOOKUP(A15,Odds!A41:I41,5,FALSE) -> 0.18894 | I15: =VLOOKUP(A15,'Yahoo WPW'!A41:I41,5,FALSE) -> 0.0648 | J15: =H15-I15 -> 0.12414 | K15: =J15*H15 -> 0.023455012 | L15: =VLOOKUP(A15,Odds!A41:I41,6,FALSE) -> 0.11266 | M15: =VLOOKUP(A15,'Yahoo WPW'!A41:I41,6,FALSE) -> 0.037 | N15: =L15-M15 -> 0.07566 | O15: =N15*L15 -> 0.0085238556 | P15: =VLOOKUP(A15,Odds!A41:I41,7,FALSE) -> 0.05283 | Q15: =VLOOKUP(A15,'Yahoo WPW'!A41:I41,7,FALSE) -> 0.0199 | R15: =P15-Q15 -> 0.03293 | S15: =R15*P15 -> 0.0017396919 | T15: =VLOOKUP(A15,Odds!A41:I41,8,FALSE) -> 0.01883 | U15: =VLOOKUP(A15,'Yahoo WPW'!A41:I41,8,FALSE) -> 0.0043 | V15: =T15-U15 -> 0.01453 | W15: =V15*T15 -> 0.0002735999 | X15: =VLOOKUP(A15,Odds!A41:I41,9,FALSE) -> 0.00686 | Y15: =VLOOKUP(A15,'Yahoo WPW'!A41:I41,9,FALSE) -> 0.0018 | Z15: =X15-Y15 -> 0.00506 | AA15: =Z15*X15 -> 3.47116e-05
A16: Wisconsin | B16: 3 | C16: East | D16: =VLOOKUP(A16,Odds!A4:I4,4,FALSE) -> 0.88488 | E16: =VLOOKUP(A16,'Yahoo WPW'!A4:I4,4,FALSE) -> 0.9184 | F16: =D16-E16 -> -0.03352 | G16: =F16*D16 -> -0.029661178 | H16: =VLOOKUP(A16,Odds!A4:I4,5,FALSE) -> 0.48478 | I16: =VLOOKUP(A16,'Yahoo WPW'!A4:I4,5,FALSE) -> 0.6027 | J16: =H16-I16 -> -0.11792 | K16: =J16*H16 -> -0.057165258 | L16: =VLOOKUP(A16,Odds!A4:I4,6,FALSE) -> 0.22908 | M16: =VLOOKUP(A16,'Yahoo WPW'!A4:I4,6,FALSE) -> 0.2287 | N16: =L16-M16 -> 0.00038 | O16: =N16*L16 -> 8.70504e-05 | P16: =VLOOKUP(A16,Odds!A4:I4,7,FALSE) -> 0.08808 | Q16: =VLOOKUP(A16,'Yahoo WPW'!A4:I4,7,FALSE) -> 0.0583 | R16: =P16-Q16 -> 0.02978 | S16: =R16*P16 -> 0.0026230224 | T16: =VLOOKUP(A16,Odds!A4:I4,8,FALSE) -> 0.03403 | U16: =VLOOKUP(A16,'Yahoo WPW'!A4:I4,8,FALSE) -> 0.0248 | V16: =T16-U16 -> 0.00923 | W16: =V16*T16 -> 0.0003140969 | X16: =VLOOKUP(A16,Odds!A4:I4,9,FALSE) -> 0.01209 | Y16: =VLOOKUP(A16,'Yahoo WPW'!A4:I4,9,FALSE) -> 0.0105 | Z16: =X16-Y16 -> 0.00159 | AA16: =Z16*X16 -> 1.92231e-05
A17: BYU | B17: 6 | C17: East | D17: =VLOOKUP(A17,Odds!A7:I7,4,FALSE) -> 0.53649 | E17: =VLOOKUP(A17,'Yahoo WPW'!A7:I7,4,FALSE) -> 0.6549 | F17: =D17-E17 -> -0.11841 | G17: =F17*D17 -> -0.063525781 | H17: =VLOOKUP(A17,Odds!A7:I7,5,FALSE) -> 0.27729 | I17: =VLOOKUP(A17,'Yahoo WPW'!A7:I7,5,FALSE) -> 0.2791 | J17: =H17-I17 -> -0.00181 | K17: =J17*H17 -> -0.0005018949 | L17: =VLOOKUP(A17,Odds!A7:I7,6,FALSE) -> 0.12161 | M17: =VLOOKUP(A17,'Yahoo WPW'!A7:I7,6,FALSE) -> 0.1121 | N17: =L17-M17 -> 0.00951 | O17: =N17*L17 -> 0.0011565111 | P17: =VLOOKUP(A17,Odds!A7:I7,7,FALSE) -> 0.04365 | Q17: =VLOOKUP(A17,'Yahoo WPW'!A7:I7,7,FALSE) -> 0.0122 | R17: =P17-Q17 -> 0.03145 | S17: =R17*P17 -> 0.0013727925 | T17: =VLOOKUP(A17,Odds!A7:I7,8,FALSE) -> 0.01547 | U17: =VLOOKUP(A17,'Yahoo WPW'!A7:I7,8,FALSE) -> 0.0043 | V17: =T17-U17 -> 0.01117 | W17: =V17*T17 -> 0.0001727999 | X17: =VLOOKUP(A17,Odds!A7:I7,9,FALSE) -> 0.00491 | Y17: =VLOOKUP(A17,'Yahoo WPW'!A7:I7,9,FALSE) -> 0.0022 | Z17: =X17-Y17 -> 0.00271 | AA17: =Z17*X17 -> 1.33061e-05
A18: Illinois | B18: 6 | C18: Midwest | D18: =VLOOKUP(A18,Odds!A23:I23,4,FALSE) -> 0.55831 | E18: =VLOOKUP(A18,'Yahoo WPW'!A23:I23,4,FALSE) -> 0.7386 | F18: =D18-E18 -> -0.18029 | G18: =F18*D18 -> -0.10065771 | H18: =VLOOKUP(A18,Odds!A23:I23,5,FALSE) -> 0.34176 | I18: =VLOOKUP(A18,'Yahoo WPW'!A23:I23,5,FALSE) -> 0.264 | J18: =H18-I18 -> 0.07776 | K18: =J18*H18 -> 0.026575258 | L18: =VLOOKUP(A18,Odds!A23:I23,6,FALSE) -> 0.14029 | M18: =VLOOKUP(A18,'Yahoo WPW'!A23:I23,6,FALSE) -> 0.0985 | N18: =L18-M18 -> 0.04179 | O18: =N18*L18 -> 0.0058627191 | P18: =VLOOKUP(A18,Odds!A23:I23,7,FALSE) -> 0.04396 | Q18: =VLOOKUP(A18,'Yahoo WPW'!A23:I23,7,FALSE) -> 0.0176 | R18: =P18-Q18 -> 0.02636 | S18: =R18*P18 -> 0.0011587856 | T18: =VLOOKUP(A18,Odds!A23:I23,8,FALSE) -> 0.01474 | U18: =VLOOKUP(A18,'Yahoo WPW'!A23:I23,8,FALSE) -> 0.0055 | V18: =T18-U18 -> 0.00924 | W18: =V18*T18 -> 0.0001361976 | X18: =VLOOKUP(A18,Odds!A23:I23,9,FALSE) -> 0.00435 | Y18: =VLOOKUP(A18,'Yahoo WPW'!A23:I23,9,FALSE) -> 0.0026 | Z18: =X18-Y18 -> 0.00175 | AA18: =Z18*X18 -> 7.6125e-06
A19: VCU | B19: 11 | C19: East | D19: =VLOOKUP(A19,Odds!A12:I12,4,FALSE) -> 0.46351 | E19: =VLOOKUP(A19,'Yahoo WPW'!A12:I12,4,FALSE) -> 0.3143 | F19: =D19-E19 -> 0.14921 | G19: =F19*D19 -> 0.069160327 | H19: =VLOOKUP(A19,Odds!A12:I12,5,FALSE) -> 0.22199 | I19: =VLOOKUP(A19,'Yahoo WPW'!A12:I12,5,FALSE) -> 0.0792 | J19: =H19-I19 -> 0.14279 | K19: =J19*H19 -> 0.031697952 | L19: =VLOOKUP(A19,Odds!A12:I12,6,FALSE) -> 0.08886 | M19: =VLOOKUP(A19,'Yahoo WPW'!A12:I12,6,FALSE) -> 0.0153 | N19: =L19-M19 -> 0.07356 | O19: =N19*L19 -> 0.0065365416 | P19: =VLOOKUP(A19,Odds!A12:I12,7,FALSE) -> 0.0284 | Q19: =VLOOKUP(A19,'Yahoo WPW'!A12:I12,7,FALSE) -> 0.0031 | R19: =P19-Q19 -> 0.0253 | S19: =R19*P19 -> 0.00071852 | T19: =VLOOKUP(A19,Odds!A12:I12,8,FALSE) -> 0.00926 | U19: =VLOOKUP(A19,'Yahoo WPW'!A12:I12,8,FALSE) -> 0.0014 | V19: =T19-U19 -> 0.00786 | W19: =V19*T19 -> 7.27836e-05 | X19: =VLOOKUP(A19,Odds!A12:I12,9,FALSE) -> 0.00306 | Y19: =VLOOKUP(A19,'Yahoo WPW'!A12:I12,9,FALSE) -> 0.0006 | Z19: =X19-Y19 -> 0.00246 | AA19: =Z19*X19 -> 7.5276e-06
A20: North Carolina | B20: 11 | C20: South | D20: =VLOOKUP(A20,Odds!A44:I44,4,FALSE) -> 0.57019 | E20: =VLOOKUP(A20,'Yahoo WPW'!A44:I44,4,FALSE) -> 0.3195 | F20: =D20-E20 -> 0.25069 | G20: =F20*D20 -> 0.14294093 | H20: =VLOOKUP(A20,Odds!A44:I44,5,FALSE) -> 0.28928 | I20: =VLOOKUP(A20,'Yahoo WPW'!A44:I44,5,FALSE) -> 0.1023 | J20: =H20-I20 -> 0.18698 | K20: =J20*H20 -> 0.054089574 | L20: =VLOOKUP(A20,Odds!A44:I44,6,FALSE) -> 0.10938 | M20: =VLOOKUP(A20,'Yahoo WPW'!A44:I44,6,FALSE) -> 0.0203 | N20: =L20-M20 -> 0.08908 | O20: =N20*L20 -> 0.0097435704 | P20: =VLOOKUP(A20,Odds!A44:I44,7,FALSE) -> 0.04146 | Q20: =VLOOKUP(A20,'Yahoo WPW'!A44:I44,7,FALSE) -> 0.0065 | R20: =P20-Q20 -> 0.03496 | S20: =R20*P20 -> 0.0014494416 | T20: =VLOOKUP(A20,Odds!A44:I44,8,FALSE) -> 0.01265 | U20: =VLOOKUP(A20,'Yahoo WPW'!A44:I44,8,FALSE) -> 0.0033 | V20: =T20-U20 -> 0.00935 | W20: =V20*T20 -> 0.0001182775 | X20: =VLOOKUP(A20,Odds!A44:I44,9,FALSE) -> 0.00384 | Y20: =VLOOKUP(A20,'Yahoo WPW'!A44:I44,9,FALSE) -> 0.0022 | Z20: =X20-Y20 -> 0.00164 | AA20: =Z20*X20 -> 6.2976e-06
A21: Marquette | B21: 7 | C21: South | D21: =VLOOKUP(A21,Odds!A40:I40,4,FALSE) -> 0.52204 | E21: =VLOOKUP(A21,'Yahoo WPW'!A40:I40,4,FALSE) -> 0.6444 | F21: =D21-E21 -> -0.12236 | G21: =F21*D21 -> -0.063876814 | H21: =VLOOKUP(A21,Odds!A40:I40,5,FALSE) -> 0.17764 | I21: =VLOOKUP(A21,'Yahoo WPW'!A40:I40,5,FALSE) -> 0.1458 | J21: =H21-I21 -> 0.03184 | K21: =J21*H21 -> 0.0056560576 | L21: =VLOOKUP(A21,Odds!A40:I40,6,FALSE) -> 0.08799 | M21: =VLOOKUP(A21,'Yahoo WPW'!A40:I40,6,FALSE) -> 0.0509 | N21: =L21-M21 -> 0.03709 | O21: =N21*L21 -> 0.0032635491 | P21: =VLOOKUP(A21,Odds!A40:I40,7,FALSE) -> 0.03303 | Q21: =VLOOKUP(A21,'Yahoo WPW'!A40:I40,7,FALSE) -> 0.0116 | R21: =P21-Q21 -> 0.02143 | S21: =R21*P21 -> 0.0007078329 | T21: =VLOOKUP(A21,Odds!A40:I40,8,FALSE) -> 0.0099 | U21: =VLOOKUP(A21,'Yahoo WPW'!A40:I40,8,FALSE) -> 0.0038 | V21: =T21-U21 -> 0.0061 | W21: =V21*T21 -> 6.039e-05 | X21: =VLOOKUP(A21,Odds!A40:I40,9,FALSE) -> 0.00295 | Y21: =VLOOKUP(A21,'Yahoo WPW'!A40:I40,9,FALSE) -> 0.0015 | Z21: =X21-Y21 -> 0.00145 | AA21: =Z21*X21 -> 4.2775e-06
A22: Texas A&M | B22: 4 | C22: South | D22: =VLOOKUP(A22,Odds!A37:I37,4,FALSE) -> 0.67588 | E22: =VLOOKUP(A22,'Yahoo WPW'!A37:I37,4,FALSE) -> 0.7753 | F22: =D22-E22 -> -0.09942 | G22: =F22*D22 -> -0.06719599 | H22: =VLOOKUP(A22,Odds!A37:I37,5,FALSE) -> 0.3434 | I22: =VLOOKUP(A22,'Yahoo WPW'!A37:I37,5,FALSE) -> 0.3524 | J22: =H22-I22 -> -0.009 | K22: =J22*H22 -> -0.0030906 | L22: =VLOOKUP(A22,Odds!A37:I37,6,FALSE) -> 0.10927 | M22: =VLOOKUP(A22,'Yahoo WPW'!A37:I37,6,FALSE) -> 0.0649 | N22: =L22-M22 -> 0.04437 | O22: =N22*L22 -> 0.0048483099 | P22: =VLOOKUP(A22,Odds!A37:I37,7,FALSE) -> 0.04527 | Q22: =VLOOKUP(A22,'Yahoo WPW'!A37:I37,7,FALSE) -> 0.0274 | R22: =P22-Q22 -> 0.01787 | S22: =R22*P22 -> 0.0008089749 | T22: =VLOOKUP(A22,Odds!A37:I37,8,FALSE) -> 0.01379 | U22: =VLOOKUP(A22,'Yahoo WPW'!A37:I37,8,FALSE) -> 0.0093 | V22: =T22-U22 -> 0.00449 | W22: =V22*T22 -> 6.19171e-05 | X22: =VLOOKUP(A22,Odds!A37:I37,9,FALSE) -> 0.00403 | Y22: =VLOOKUP(A22,'Yahoo WPW'!A37:I37,9,FALSE) -> 0.0031 | Z22: =X22-Y22 -> 0.00093 | AA22: =Z22*X22 -> 3.7479e-06
A23: New Mexico | B23: 10 | C23: South | D23: =VLOOKUP(A23,Odds!A43:I43,4,FALSE) -> 0.47796 | E23: =VLOOKUP(A23,'Yahoo WPW'!A43:I43,4,FALSE) -> 0.3367 | F23: =D23-E23 -> 0.14126 | G23: =F23*D23 -> 0.06751663 | H23: =VLOOKUP(A23,Odds!A43:I43,5,FALSE) -> 0.15451 | I23: =VLOOKUP(A23,'Yahoo WPW'!A43:I43,5,FALSE) -> 0.0387 | J23: =H23-I23 -> 0.11581 | K23: =J23*H23 -> 0.017893803 | L23: =VLOOKUP(A23,Odds!A43:I43,6,FALSE) -> 0.07328 | M23: =VLOOKUP(A23,'Yahoo WPW'!A43:I43,6,FALSE) -> 0.0136 | N23: =L23-M23 -> 0.05968 | O23: =N23*L23 -> 0.0043733504 | P23: =VLOOKUP(A23,Odds!A43:I43,7,FALSE) -> 0.02483 | Q23: =VLOOKUP(A23,'Yahoo WPW'!A43:I43,7,FALSE) -> 0.0035 | R23: =P23-Q23 -> 0.02133 | S23: =R23*P23 -> 0.0005296239 | T23: =VLOOKUP(A23,Odds!A43:I43,8,FALSE) -> 0.00661 | U23: =VLOOKUP(A23,'Yahoo WPW'!A43:I43,8,FALSE) -> 0.0013 | V23: =T23-U23 -> 0.00531 | W23: =V23*T23 -> 3.50991e-05 | X23: =VLOOKUP(A23,Odds!A43:I43,9,FALSE) -> 0.00188 | Y23: =VLOOKUP(A23,'Yahoo WPW'!A43:I43,9,FALSE) -> 0.0006 | Z23: =X23-Y23 -> 0.00128 | AA23: =Z23*X23 -> 2.4064e-06
A24: Drake | B24: 11 | C24: West | D24: =VLOOKUP(A24,Odds!A60:I60,4,FALSE) -> 0.54398 | E24: =VLOOKUP(A24,'Yahoo WPW'!A60:I60,4,FALSE) -> 0.383 | F24: =D24-E24 -> 0.16098 | G24: =F24*D24 -> 0.0875699 | H24: =VLOOKUP(A24,Odds!A60:I60,5,FALSE) -> 0.22555 | I24: =VLOOKUP(A24,'Yahoo WPW'!A60:I60,5,FALSE) -> 0.1219 | J24: =H24-I24 -> 0.10365 | K24: =J24*H24 -> 0.023378258 | L24: =VLOOKUP(A24,Odds!A60:I60,6,FALSE) -> 0.07472 | M24: =VLOOKUP(A24,'Yahoo WPW'!A60:I60,6,FALSE) -> 0.0245 | N24: =L24-M24 -> 0.05022 | O24: =N24*L24 -> 0.0037524384 | P24: =VLOOKUP(A24,Odds!A60:I60,7,FALSE) -> 0.02051 | Q24: =VLOOKUP(A24,'Yahoo WPW'!A60:I60,7,FALSE) -> 0.0059 | R24: =P24-Q24 -> 0.01461 | S24: =R24*P24 -> 0.0002996511 | T24: =VLOOKUP(A24,Odds!A60:I60,8,FALSE) -> 0.00696 | U24: =VLOOKUP(A24,'Yahoo WPW'!A60:I60,8,FALSE) -> 0.0025 | V24: =T24-U24 -> 0.00446 | W24: =V24*T24 -> 3.10416e-05 | X24: =VLOOKUP(A24,Odds!A60:I60,9,FALSE) -> 0.00203 | Y24: =VLOOKUP(A24,'Yahoo WPW'!A60:I60,9,FALSE) -> 0.0009 | Z24: =X24-Y24 -> 0.00113 | AA24: =Z24*X24 -> 2.2939e-06
A25: UC San Diego | B25: 12 | C25: South | D25: =VLOOKUP(A25,Odds!A45:I45,4,FALSE) -> 0.44439 | E25: =VLOOKUP(A25,'Yahoo WPW'!A45:I45,4,FALSE) -> 0.1931 | F25: =D25-E25 -> 0.25129 | G25: =F25*D25 -> 0.11167076 | H25: =VLOOKUP(A25,Odds!A45:I45,5,FALSE) -> 0.23225 | I25: =VLOOKUP(A25,'Yahoo WPW'!A45:I45,5,FALSE) -> 0.0827 | J25: =H25-I25 -> 0.14955 | K25: =J25*H25 -> 0.034732988 | L25: =VLOOKUP(A25,Odds!A45:I45,6,FALSE) -> 0.06714 | M25: =VLOOKUP(A25,'Yahoo WPW'!A45:I45,6,FALSE) -> 0.0115 | N25: =L25-M25 -> 0.05564 | O25: =N25*L25 -> 0.0037356696 | P25: =VLOOKUP(A25,Odds!A45:I45,7,FALSE) -> 0.02463 | Q25: =VLOOKUP(A25,'Yahoo WPW'!A45:I45,7,FALSE) -> 0.0052 | R25: =P25-Q25 -> 0.01943 | S25: =R25*P25 -> 0.0004785609 | T25: =VLOOKUP(A25,Odds!A45:I45,8,FALSE) -> 0.00662 | U25: =VLOOKUP(A25,'Yahoo WPW'!A45:I45,8,FALSE) -> 0.0021 | V25: =T25-U25 -> 0.00452 | W25: =V25*T25 -> 2.99224e-05 | X25: =VLOOKUP(A25,Odds!A45:I45,9,FALSE) -> 0.00202 | Y25: =VLOOKUP(A25,'Yahoo WPW'!A45:I45,9,FALSE) -> 0.0009 | Z25: =X25-Y25 -> 0.00112 | AA25: =Z25*X25 -> 2.2624e-06
A26: Creighton | B26: 9 | C26: South | D26: =VLOOKUP(A26,Odds!A42:I42,4,FALSE) -> 0.42737 | E26: =VLOOKUP(A26,'Yahoo WPW'!A42:I42,4,FALSE) -> 0.4391 | F26: =D26-E26 -> -0.01173 | G26: =F26*D26 -> -0.0050130501 | H26: =VLOOKUP(A26,Odds!A42:I42,5,FALSE) -> 0.11519 | I26: =VLOOKUP(A26,'Yahoo WPW'!A42:I42,5,FALSE) -> 0.0457 | J26: =H26-I26 -> 0.06949 | K26: =J26*H26 -> 0.0080045531 | L26: =VLOOKUP(A26,Odds!A42:I42,6,FALSE) -> 0.06015 | M26: =VLOOKUP(A26,'Yahoo WPW'!A42:I42,6,FALSE) -> 0.0202 | N26: =L26-M26 -> 0.03995 | O26: =N26*L26 -> 0.0024029925 | P26: =VLOOKUP(A26,Odds!A42:I42,7,FALSE) -> 0.02437 | Q26: =VLOOKUP(A26,'Yahoo WPW'!A42:I42,7,FALSE) -> 0.0079 | R26: =P26-Q26 -> 0.01647 | S26: =R26*P26 -> 0.0004013739 | T26: =VLOOKUP(A26,Odds!A42:I42,8,FALSE) -> 0.00708 | U26: =VLOOKUP(A26,'Yahoo WPW'!A42:I42,8,FALSE) -> 0.0028 | V26: =T26-U26 -> 0.00428 | W26: =V26*T26 -> 3.03024e-05 | X26: =VLOOKUP(A26,Odds!A42:I42,9,FALSE) -> 0.00215 | Y26: =VLOOKUP(A26,'Yahoo WPW'!A42:I42,9,FALSE) -> 0.0013 | Z26: =X26-Y26 -> 0.00085 | AA26: =Z26*X26 -> 1.8275e-06
A27: Xavier | B27: 11 | C27: Midwest | D27: =VLOOKUP(A27,Odds!A28:I28,4,FALSE) -> 0.44169 | E27: =VLOOKUP(A27,'Yahoo WPW'!A28:I28,4,FALSE) -> 0.2246 | F27: =D27-E27 -> 0.21709 | G27: =F27*D27 -> 0.095886482 | H27: =VLOOKUP(A27,Odds!A28:I28,5,FALSE) -> 0.24541 | I27: =VLOOKUP(A27,'Yahoo WPW'!A28:I28,5,FALSE) -> 0.0571 | J27: =H27-I27 -> 0.18831 | K27: =J27*H27 -> 0.046213157 | L27: =VLOOKUP(A27,Odds!A28:I28,6,FALSE) -> 0.08805 | M27: =VLOOKUP(A27,'Yahoo WPW'!A28:I28,6,FALSE) -> 0.0107 | N27: =L27-M27 -> 0.07735 | O27: =N27*L27 -> 0.0068106675 | P27: =VLOOKUP(A27,Odds!A28:I28,7,FALSE) -> 0.02337 | Q27: =VLOOKUP(A27,'Yahoo WPW'!A28:I28,7,FALSE) -> 0.0032 | R27: =P27-Q27 -> 0.02017 | S27: =R27*P27 -> 0.0004713729 | T27: =VLOOKUP(A27,Odds!A28:I28,8,FALSE) -> 0.00669 | U27: =VLOOKUP(A27,'Yahoo WPW'!A28:I28,8,FALSE) -> 0.0013 | V27: =T27-U27 -> 0.00539 | W27: =V27*T27 -> 3.60591e-05 | X27: =VLOOKUP(A27,Odds!A28:I28,9,FALSE) -> 0.00162 | Y27: =VLOOKUP(A27,'Yahoo WPW'!A28:I28,9,FALSE) -> 0.0007 | Z27: =X27-Y27 -> 0.00092 | AA27: =Z27*X27 -> 1.4904e-06
A28: Colorado State | B28: 12 | C28: West | D28: =VLOOKUP(A28,Odds!A61:I61,4,FALSE) -> 0.47591 | E28: =VLOOKUP(A28,'Yahoo WPW'!A61:I61,4,FALSE) -> 0.2779 | F28: =D28-E28 -> 0.19801 | G28: =F28*D28 -> 0.094234939 | H28: =VLOOKUP(A28,Odds!A61:I61,5,FALSE) -> 0.18138 | I28: =VLOOKUP(A28,'Yahoo WPW'!A61:I61,5,FALSE) -> 0.0683 | J28: =H28-I28 -> 0.11308 | K28: =J28*H28 -> 0.02051045 | L28: =VLOOKUP(A28,Odds!A61:I61,6,FALSE) -> 0.04171 | M28: =VLOOKUP(A28,'Yahoo WPW'!A61:I61,6,FALSE) -> 0.0084 | N28: =L28-M28 -> 0.03331 | O28: =N28*L28 -> 0.0013893601 | P28: =VLOOKUP(A28,Odds!A61:I61,7,FALSE) -> 0.01384 | Q28: =VLOOKUP(A28,'Yahoo WPW'!A61:I61,7,FALSE) -> 0.0034 | R28: =P28-Q28 -> 0.01044 | S28: =R28*P28 -> 0.0001444896 | T28: =VLOOKUP(A28,Odds!A61:I61,8,FALSE) -> 0.00442 | U28: =VLOOKUP(A28,'Yahoo WPW'!A61:I61,8,FALSE) -> 0.0015 | V28: =T28-U28 -> 0.00292 | W28: =V28*T28 -> 1.29064e-05 | X28: =VLOOKUP(A28,Odds!A61:I61,9,FALSE) -> 0.00113 | Y28: =VLOOKUP(A28,'Yahoo WPW'!A61:I61,9,FALSE) -> 0.0007 | Z28: =X28-Y28 -> 0.00043 | AA28: =Z28*X28 -> 4.859e-07
A29: Baylor | B29: 9 | C29: East | D29: =VLOOKUP(A29,Odds!A10:I10,4,FALSE) -> 0.57797 | E29: =VLOOKUP(A29,'Yahoo WPW'!A10:I10,4,FALSE) -> 0.5472 | F29: =D29-E29 -> 0.03077 | G29: =F29*D29 -> 0.017784137 | H29: =VLOOKUP(A29,Odds!A10:I10,5,FALSE) -> 0.12217 | I29: =VLOOKUP(A29,'Yahoo WPW'!A10:I10,5,FALSE) -> 0.0379 | J29: =H29-I29 -> 0.08427 | K29: =J29*H29 -> 0.010295266 | L29: =VLOOKUP(A29,Odds!A10:I10,6,FALSE) -> 0.05358 | M29: =VLOOKUP(A29,'Yahoo WPW'!A10:I10,6,FALSE) -> 0.0148 | N29: =L29-M29 -> 0.03878 | O29: =N29*L29 -> 0.0020778324 | P29: =VLOOKUP(A29,Odds!A10:I10,7,FALSE) -> 0.01996 | Q29: =VLOOKUP(A29,'Yahoo WPW'!A10:I10,7,FALSE) -> 0.0067 | R29: =P29-Q29 -> 0.01326 | S29: =R29*P29 -> 0.0002646696 | T29: =VLOOKUP(A29,Odds!A10:I10,8,FALSE) -> 0.0059 | U29: =VLOOKUP(A29,'Yahoo WPW'!A10:I10,8,FALSE) -> 0.0027 | V29: =T29-U29 -> 0.0032 | W29: =V29*T29 -> 1.888e-05 | X29: =VLOOKUP(A29,Odds!A10:I10,9,FALSE) -> 0.00156 | Y29: =VLOOKUP(A29,'Yahoo WPW'!A10:I10,9,FALSE) -> 0.0013 | Z29: =X29-Y29 -> 0.00026 | AA29: =Z29*X29 -> 4.056e-07
A30: Utah State | B30: 10 | C30: Midwest | D30: =VLOOKUP(A30,Odds!A27:I27,4,FALSE) -> 0.43968 | E30: =VLOOKUP(A30,'Yahoo WPW'!A27:I27,4,FALSE) -> 0.313 | F30: =D30-E30 -> 0.12668 | G30: =F30*D30 -> 0.055698662 | H30: =VLOOKUP(A30,Odds!A27:I27,5,FALSE) -> 0.11395 | I30: =VLOOKUP(A30,'Yahoo WPW'!A27:I27,5,FALSE) -> 0.0318 | J30: =H30-I30 -> 0.08215 | K30: =J30*H30 -> 0.0093609925 | L30: =VLOOKUP(A30,Odds!A27:I27,6,FALSE) -> 0.04769 | M30: =VLOOKUP(A30,'Yahoo WPW'!A27:I27,6,FALSE) -> 0.0097 | N30: =L30-M30 -> 0.03799 | O30: =N30*L30 -> 0.0018117431 | P30: =VLOOKUP(A30,Odds!A27:I27,7,FALSE) -> 0.00997 | Q30: =VLOOKUP(A30,'Yahoo WPW'!A27:I27,7,FALSE) -> 0.0029 | R30: =P30-Q30 -> 0.00707 | S30: =R30*P30 -> 7.04879e-05 | T30: =VLOOKUP(A30,Odds!A27:I27,8,FALSE) -> 0.00217 | U30: =VLOOKUP(A30,'Yahoo WPW'!A27:I27,8,FALSE) -> 0.0011 | V30: =T30-U30 -> 0.00107 | W30: =V30*T30 -> 2.3219e-06 | X30: =VLOOKUP(A30,Odds!A27:I27,9,FALSE) -> 0.00046 | Y30: =VLOOKUP(A30,'Yahoo WPW'!A27:I27,9,FALSE) -> 0.0004 | Z30: =X30-Y30 -> 6e-05 | AA30: =Z30*X30 -> 2.76e-08
A31: Akron | B31: 13 | C31: East | D31: =VLOOKUP(A31,Odds!A14:I14,4,FALSE) -> 0.14208 | E31: =VLOOKUP(A31,'Yahoo WPW'!A14:I14,4,FALSE) -> 0.1202 | F31: =D31-E31 -> 0.02188 | G31: =F31*D31 -> 0.0031087104 | H31: =VLOOKUP(A31,Odds!A14:I14,5,FALSE) -> 0.03649 | I31: =VLOOKUP(A31,'Yahoo WPW'!A14:I14,5,FALSE) -> 0.0423 | J31: =H31-I31 -> -0.00581 | K31: =J31*H31 -> -0.0002120069 | L31: =VLOOKUP(A31,Odds!A14:I14,6,FALSE) -> 0.00403 | M31: =VLOOKUP(A31,'Yahoo WPW'!A14:I14,6,FALSE) -> 0.0062 | N31: =L31-M31 -> -0.00217 | O31: =N31*L31 -> -8.7451e-06 | P31: =VLOOKUP(A31,Odds!A14:I14,7,FALSE) -> 0.00051 | Q31: =VLOOKUP(A31,'Yahoo WPW'!A14:I14,7,FALSE) -> 0.0024 | R31: =P31-Q31 -> -0.00189 | S31: =R31*P31 -> -9.639e-07 | T31: =VLOOKUP(A31,Odds!A14:I14,8,FALSE) -> 4e-05 | U31: =VLOOKUP(A31,'Yahoo WPW'!A14:I14,8,FALSE) -> 0.0011 | V31: =T31-U31 -> -0.00106 | W31: =V31*T31 -> -4.24e-08 | X31: =VLOOKUP(A31,Odds!A14:I14,9,FALSE) -> 0 | Y31: =VLOOKUP(A31,'Yahoo WPW'!A14:I14,9,FALSE) -> 0.0006 | Z31: =X31-Y31 -> -0.0006 | AA31: =Z31*X31 -> 0
A32: Montana | B32: 14 | C32: East | D32: =VLOOKUP(A32,Odds!A15:I15,4,FALSE) -> 0.11512 | E32: =VLOOKUP(A32,'Yahoo WPW'!A15:I15,4,FALSE) -> 0.0557 | F32: =D32-E32 -> 0.05942 | G32: =F32*D32 -> 0.0068404304 | H32: =VLOOKUP(A32,Odds!A15:I15,5,FALSE) -> 0.01594 | I32: =VLOOKUP(A32,'Yahoo WPW'!A15:I15,5,FALSE) -> 0.0177 | J32: =H32-I32 -> -0.00176 | K32: =J32*H32 -> -2.80544e-05 | L32: =VLOOKUP(A32,Odds!A15:I15,6,FALSE) -> 0.00168 | M32: =VLOOKUP(A32,'Yahoo WPW'!A15:I15,6,FALSE) -> 0.0054 | N32: =L32-M32 -> -0.00372 | O32: =N32*L32 -> -6.2496e-06 | P32: =VLOOKUP(A32,Odds!A15:I15,7,FALSE) -> 0.00013 | Q32: =VLOOKUP(A32,'Yahoo WPW'!A15:I15,7,FALSE) -> 0.0023 | R32: =P32-Q32 -> -0.00217 | S32: =R32*P32 -> -2.821e-07 | T32: =VLOOKUP(A32,Odds!A15:I15,8,FALSE) -> 1e-05 | U32: =VLOOKUP(A32,'Yahoo WPW'!A15:I15,8,FALSE) -> 0.001 | V32: =T32-U32 -> -0.00099 | W32: =V32*T32 -> -9.9e-09 | X32: =VLOOKUP(A32,Odds!A15:I15,9,FALSE) -> 0 | Y32: =VLOOKUP(A32,'Yahoo WPW'!A15:I15,9,FALSE) -> 0.0005 | Z32: =X32-Y32 -> -0.0005 | AA32: =Z32*X32 -> 0
A33: Robert Morris | B33: 15 | C33: East | D33: =VLOOKUP(A33,Odds!A16:I16,4,FALSE) -> 0.09691 | E33: =VLOOKUP(A33,'Yahoo WPW'!A16:I16,4,FALSE) -> 0.0323 | F33: =D33-E33 -> 0.06461 | G33: =F33*D33 -> 0.0062613551 | H33: =VLOOKUP(A33,Odds!A16:I16,5,FALSE) -> 0.01934 | I33: =VLOOKUP(A33,'Yahoo WPW'!A16:I16,5,FALSE) -> 0.0123 | J33: =H33-I33 -> 0.00704 | K33: =J33*H33 -> 0.0001361536 | L33: =VLOOKUP(A33,Odds!A16:I16,6,FALSE) -> 0.00294 | M33: =VLOOKUP(A33,'Yahoo WPW'!A16:I16,6,FALSE) -> 0.0054 | N33: =L33-M33 -> -0.00246 | O33: =N33*L33 -> -7.2324e-06 | P33: =VLOOKUP(A33,Odds!A16:I16,7,FALSE) -> 0.00026 | Q33: =VLOOKUP(A33,'Yahoo WPW'!A16:I16,7,FALSE) -> 0.0022 | R33: =P33-Q33 -> -0.00194 | S33: =R33*P33 -> -5.044e-07 | T33: =VLOOKUP(A33,Odds!A16:I16,8,FALSE) -> 3e-05 | U33: =VLOOKUP(A33,'Yahoo WPW'!A16:I16,8,FALSE) -> 0.0009 | V33: =T33-U33 -> -0.00087 | W33: =V33*T33 -> -2.61e-08 | X33: =VLOOKUP(A33,Odds!A16:I16,9,FALSE) -> 0 | Y33: =VLOOKUP(A33,'Yahoo WPW'!A16:I16,9,FALSE) -> 0.0004 | Z33: =X33-Y33 -> -0.0004 | AA33: =Z33*X33 -> 0
A34: Mount St. Mary's | B34: 16 | C34: East | D34: =VLOOKUP(A34,Odds!A17:I17,4,FALSE) -> 0.02879 | E34: =VLOOKUP(A34,'Yahoo WPW'!A17:I17,4,FALSE) -> 0.0163 | F34: =D34-E34 -> 0.01249 | G34: =F34*D34 -> 0.0003595871 | H34: =VLOOKUP(A34,Odds!A17:I17,5,FALSE) -> 0.00363 | I34: =VLOOKUP(A34,'Yahoo WPW'!A17:I17,5,FALSE) -> 0.0075 | J34: =H34-I34 -> -0.00387 | K34: =J34*H34 -> -1.40481e-05 | L34: =VLOOKUP(A34,Odds!A17:I17,6,FALSE) -> 0.00036 | M34: =VLOOKUP(A34,'Yahoo WPW'!A17:I17,6,FALSE) -> 0.0038 | N34: =L34-M34 -> -0.00344 | O34: =N34*L34 -> -1.2384e-06 | P34: =VLOOKUP(A34,Odds!A17:I17,7,FALSE) -> 0 | Q34: =VLOOKUP(A34,'Yahoo WPW'!A17:I17,7,FALSE) -> 0.0022 | R34: =P34-Q34 -> -0.0022 | S34: =R34*P34 -> 0 | T34: =VLOOKUP(A34,Odds!A17:I17,8,FALSE) -> 0 | U34: =VLOOKUP(A34,'Yahoo WPW'!A17:I17,8,FALSE) -> 0.001 | V34: =T34-U34 -> -0.001 | W34: =V34*T34 -> 0 | X34: =VLOOKUP(A34,Odds!A17:I17,9,FALSE) -> 0 | Y34: =VLOOKUP(A34,'Yahoo WPW'!A17:I17,9,FALSE) -> 0.0004 | Z34: =X34-Y34 -> -0.0004 | AA34: =Z34*X34 -> 0
A35: Wofford | B35: 15 | C35: Midwest | D35: =VLOOKUP(A35,Odds!A32:I32,4,FALSE) -> 0.08781 | E35: =VLOOKUP(A35,'Yahoo WPW'!A32:I32,4,FALSE) -> 0.0336 | F35: =D35-E35 -> 0.05421 | G35: =F35*D35 -> 0.0047601801 | H35: =VLOOKUP(A35,Odds!A32:I32,5,FALSE) -> 0.02092 | I35: =VLOOKUP(A35,'Yahoo WPW'!A32:I32,5,FALSE) -> 0.0128 | J35: =H35-I35 -> 0.00812 | K35: =J35*H35 -> 0.0001698704 | L35: =VLOOKUP(A35,Odds!A32:I32,6,FALSE) -> 0.00404 | M35: =VLOOKUP(A35,'Yahoo WPW'!A32:I32,6,FALSE) -> 0.0064 | N35: =L35-M35 -> -0.00236 | O35: =N35*L35 -> -9.5344e-06 | P35: =VLOOKUP(A35,Odds!A32:I32,7,FALSE) -> 0.0003 | Q35: =VLOOKUP(A35,'Yahoo WPW'!A32:I32,7,FALSE) -> 0.0024 | R35: =P35-Q35 -> -0.0021 | S35: =R35*P35 -> -6.3e-07 | T35: =VLOOKUP(A35,Odds!A32:I32,8,FALSE) -> 6e-05 | U35: =VLOOKUP(A35,'Yahoo WPW'!A32:I32,8,FALSE) -> 0.0012 | V35: =T35-U35 -> -0.00114 | W35: =V35*T35 -> -6.84e-08 | X35: =VLOOKUP(A35,Odds!A32:I32,9,FALSE) -> 0 | Y35: =VLOOKUP(A35,'Yahoo WPW'!A32:I32,9,FALSE) -> 0.0005 | Z35: =X35-Y35 -> -0.0005 | AA35: =Z35*X35 -> 0
A36: SIU Edwardsville | B36: 16 | C36: Midwest | D36: =VLOOKUP(A36,Odds!A33:I33,4,FALSE) -> 0.0201 | E36: =VLOOKUP(A36,'Yahoo WPW'!A33:I33,4,FALSE) -> 0.0214 | F36: =D36-E36 -> -0.0013 | G36: =F36*D36 -> -2.613e-05 | H36: =VLOOKUP(A36,Odds!A33:I33,5,FALSE) -> 0.0013 | I36: =VLOOKUP(A36,'Yahoo WPW'!A33:I33,5,FALSE) -> 0.0084 | J36: =H36-I36 -> -0.0071 | K36: =J36*H36 -> -9.23e-06 | L36: =VLOOKUP(A36,Odds!A33:I33,6,FALSE) -> 0.00012 | M36: =VLOOKUP(A36,'Yahoo WPW'!A33:I33,6,FALSE) -> 0.0042 | N36: =L36-M36 -> -0.00408 | O36: =N36*L36 -> -4.896e-07 | P36: =VLOOKUP(A36,Odds!A33:I33,7,FALSE) -> 3e-05 | Q36: =VLOOKUP(A36,'Yahoo WPW'!A33:I33,7,FALSE) -> 0.0024 | R36: =P36-Q36 -> -0.00237 | S36: =R36*P36 -> -7.11e-08 | T36: =VLOOKUP(A36,Odds!A33:I33,8,FALSE) -> 0 | U36: =VLOOKUP(A36,'Yahoo WPW'!A33:I33,8,FALSE) -> 0.0011 | V36: =T36-U36 -> -0.0011 | W36: =V36*T36 -> 0 | X36: =VLOOKUP(A36,Odds!A33:I33,9,FALSE) -> 0 | Y36: =VLOOKUP(A36,'Yahoo WPW'!A33:I33,9,FALSE) -> 0.0005 | Z36: =X36-Y36 -> -0.0005 | AA36: =Z36*X36 -> 0
A37: Bryant | B37: 15 | C37: South | D37: =VLOOKUP(A37,Odds!A48:I48,4,FALSE) -> 0.08097 | E37: =VLOOKUP(A37,'Yahoo WPW'!A48:I48,4,FALSE) -> 0.0325 | F37: =D37-E37 -> 0.04847 | G37: =F37*D37 -> 0.0039246159 | H37: =VLOOKUP(A37,Odds!A48:I48,5,FALSE) -> 0.01465 | I37: =VLOOKUP(A37,'Yahoo WPW'!A48:I48,5,FALSE) -> 0.0133 | J37: =H37-I37 -> 0.00135 | K37: =J37*H37 -> 1.97775e-05 | L37: =VLOOKUP(A37,Odds!A48:I48,6,FALSE) -> 0.00235 | M37: =VLOOKUP(A37,'Yahoo WPW'!A48:I48,6,FALSE) -> 0.0064 | N37: =L37-M37 -> -0.00405 | O37: =N37*L37 -> -9.5175e-06 | P37: =VLOOKUP(A37,Odds!A48:I48,7,FALSE) -> 0.00035 | Q37: =VLOOKUP(A37,'Yahoo WPW'!A48:I48,7,FALSE) -> 0.0025 | R37: =P37-Q37 -> -0.00215 | S37: =R37*P37 -> -7.525e-07 | T37: =VLOOKUP(A37,Odds!A48:I48,8,FALSE) -> 2e-05 | U37: =VLOOKUP(A37,'Yahoo WPW'!A48:I48,8,FALSE) -> 0.0009 | V37: =T37-U37 -> -0.00088 | W37: =V37*T37 -> -1.76e-08 | X37: =VLOOKUP(A37,Odds!A48:I48,9,FALSE) -> 0 | Y37: =VLOOKUP(A37,'Yahoo WPW'!A48:I48,9,FALSE) -> 0.0004 | Z37: =X37-Y37 -> -0.0004 | AA37: =Z37*X37 -> 0
A38: Alabama St. | B38: 16 | C38: South | D38: =VLOOKUP(A38,Odds!A49:I49,4,FALSE) -> 0.01613 | E38: =VLOOKUP(A38,'Yahoo WPW'!A49:I49,4,FALSE) -> 0.0162 | F38: =D38-E38 -> -7e-05 | G38: =F38*D38 -> -1.1291e-06 | H38: =VLOOKUP(A38,Odds!A49:I49,5,FALSE) -> 0.00065 | I38: =VLOOKUP(A38,'Yahoo WPW'!A49:I49,5,FALSE) -> 0.007 | J38: =H38-I38 -> -0.00635 | K38: =J38*H38 -> -4.1275e-06 | L38: =VLOOKUP(A38,Odds!A49:I49,6,FALSE) -> 6e-05 | M38: =VLOOKUP(A38,'Yahoo WPW'!A49:I49,6,FALSE) -> 0.0038 | N38: =L38-M38 -> -0.00374 | O38: =N38*L38 -> -2.244e-07 | P38: =VLOOKUP(A38,Odds!A49:I49,7,FALSE) -> 0 | Q38: =VLOOKUP(A38,'Yahoo WPW'!A49:I49,7,FALSE) -> 0.0021 | R38: =P38-Q38 -> -0.0021 | S38: =R38*P38 -> 0 | T38: =VLOOKUP(A38,Odds!A49:I49,8,FALSE) -> 0 | U38: =VLOOKUP(A38,'Yahoo WPW'!A49:I49,8,FALSE) -> 0.001 | V38: =T38-U38 -> -0.001 | W38: =V38*T38 -> 0 | X38: =VLOOKUP(A38,Odds!A49:I49,9,FALSE) -> 0 | Y38: =VLOOKUP(A38,'Yahoo WPW'!A49:I49,9,FALSE) -> 0.0005 | Z38: =X38-Y38 -> -0.0005 | AA38: =Z38*X38 -> 0
A39: UNC Wilmington | B39: 14 | C39: West | D39: =VLOOKUP(A39,Odds!A63:I63,4,FALSE) -> 0.13795 | E39: =VLOOKUP(A39,'Yahoo WPW'!A63:I63,4,FALSE) -> 0.0599 | F39: =D39-E39 -> 0.07805 | G39: =F39*D39 -> 0.010766997 | H39: =VLOOKUP(A39,Odds!A63:I63,5,FALSE) -> 0.03298 | I39: =VLOOKUP(A39,'Yahoo WPW'!A63:I63,5,FALSE) -> 0.0181 | J39: =H39-I39 -> 0.01488 | K39: =J39*H39 -> 0.0004907424 | L39: =VLOOKUP(A39,Odds!A63:I63,6,FALSE) -> 0.00485 | M39: =VLOOKUP(A39,'Yahoo WPW'!A63:I63,6,FALSE) -> 0.0049 | N39: =L39-M39 -> -5e-05 | O39: =N39*L39 -> -2.425e-07 | P39: =VLOOKUP(A39,Odds!A63:I63,7,FALSE) -> 0.00044 | Q39: =VLOOKUP(A39,'Yahoo WPW'!A63:I63,7,FALSE) -> 0.002 | R39: =P39-Q39 -> -0.00156 | S39: =R39*P39 -> -6.864e-07 | T39: =VLOOKUP(A39,Odds!A63:I63,8,FALSE) -> 5e-05 | U39: =VLOOKUP(A39,'Yahoo WPW'!A63:I63,8,FALSE) -> 0.0009 | V39: =T39-U39 -> -0.00085 | W39: =V39*T39 -> -4.25e-08 | X39: =VLOOKUP(A39,Odds!A63:I63,9,FALSE) -> 0 | Y39: =VLOOKUP(A39,'Yahoo WPW'!A63:I63,9,FALSE) -> 0.0004 | Z39: =X39-Y39 -> -0.0004 | AA39: =Z39*X39 -> 0
A40: Omaha | B40: 15 | C40: West | D40: =VLOOKUP(A40,Odds!A64:I64,4,FALSE) -> 0.05985 | E40: =VLOOKUP(A40,'Yahoo WPW'!A64:I64,4,FALSE) -> 0.0403 | F40: =D40-E40 -> 0.01955 | G40: =F40*D40 -> 0.0011700675 | H40: =VLOOKUP(A40,Odds!A64:I64,5,FALSE) -> 0.01257 | I40: =VLOOKUP(A40,'Yahoo WPW'!A64:I64,5,FALSE) -> 0.0127 | J40: =H40-I40 -> -0.00013 | K40: =J40*H40 -> -1.6341e-06 | L40: =VLOOKUP(A40,Odds!A64:I64,6,FALSE) -> 0.00162 | M40: =VLOOKUP(A40,'Yahoo WPW'!A64:I64,6,FALSE) -> 0.0059 | N40: =L40-M40 -> -0.00428 | O40: =N40*L40 -> -6.9336e-06 | P40: =VLOOKUP(A40,Odds!A64:I64,7,FALSE) -> 8e-05 | Q40: =VLOOKUP(A40,'Yahoo WPW'!A64:I64,7,FALSE) -> 0.0024 | R40: =P40-Q40 -> -0.00232 | S40: =R40*P40 -> -1.856e-07 | T40: =VLOOKUP(A40,Odds!A64:I64,8,FALSE) -> 1e-05 | U40: =VLOOKUP(A40,'Yahoo WPW'!A64:I64,8,FALSE) -> 0.0011 | V40: =T40-U40 -> -0.00109 | W40: =V40*T40 -> -1.09e-08 | X40: =VLOOKUP(A40,Odds!A64:I64,9,FALSE) -> 0 | Y40: =VLOOKUP(A40,'Yahoo WPW'!A64:I64,9,FALSE) -> 0.0005 | Z40: =X40-Y40 -> -0.0005 | AA40: =Z40*X40 -> 0
...

Sheet Odds
A1: Team | B1: Region | C1: Seed | D1: Round_of_32 | E1: Sweet_16 | F1: Elite_8 | G1: Final_Four | H1: National_Championship | I1: National_Champion
A2: Duke | B2: East | C2: 1 | D2: 0.97121 | E2: 0.80251 | F2: 0.61207 | G2: 0.43037 | H2: 0.2599 | I2: 0.15237
A3: Alabama | B3: East | C3: 2 | D3: 0.90309 | E3: 0.59839 | F3: 0.37175 | G3: 0.17502 | H3: 0.08215 | I3: 0.03663
A4: Wisconsin | B4: East | C4: 3 | D4: 0.88488 | E4: 0.48478 | F4: 0.22908 | G4: 0.08808 | H4: 0.03403 | I4: 0.01209
A5: Arizona | B5: East | C5: 4 | D5: 0.85792 | E5: 0.56799 | F5: 0.20823 | G5: 0.10611 | H5: 0.04294 | I5: 0.01627
A6: Oregon | B6: East | C6: 5 | D6: 0.61437 | E6: 0.26631 | F6: 0.07022 | G6: 0.02688 | H6: 0.00822 | I6: 0.00223
A7: BYU | B7: East | C7: 6 | D7: 0.53649 | E7: 0.27729 | F7: 0.12161 | G7: 0.04365 | H7: 0.01547 | I7: 0.00491
A8: Saint Mary's | B8: East | C8: 7 | D8: 0.77832 | E8: 0.33945 | F8: 0.17386 | G8: 0.06482 | H8: 0.02439 | I8: 0.00867
A9: Mississippi State | B9: East | C9: 8 | D9: 0.42203 | E9: 0.07169 | F9: 0.02584 | G9: 0.00739 | H9: 0.00182 | I9: 0.00046
A10: Baylor | B10: East | C10: 9 | D10: 0.57797 | E10: 0.12217 | F10: 0.05358 | G10: 0.01996 | H10: 0.0059 | I10: 0.00156
A11: Vanderbilt | B11: East | C11: 10 | D11: 0.22168 | E11: 0.04282 | F11: 0.01022 | G11: 0.00139 | H11: 0.00025 | I11: 2e-05
A12: VCU | B12: East | C12: 11 | D12: 0.46351 | E12: 0.22199 | F12: 0.08886 | G12: 0.0284 | H12: 0.00926 | I12: 0.00306
A13: Liberty | B13: East | C13: 12 | D13: 0.38563 | E13: 0.12921 | F13: 0.02567 | G13: 0.00703 | H13: 0.00135 | I13: 0.00029
... A65: Norfolk State | B65: West | C65: 16 | D65: 0.0278 | E65: 0.0028 | F65: 0.00025 | G65: 2e-05 | H65: 0 | I65: 0

Sheet Yahoo WPW
A1: Team | B1: Region | C1: Seed | D1: Round_of_32 | E1: Sweet_16 | F1: Elite_8 | G1: Final_Four | H1: National_Championship | I1: National_Champion
A2: Duke | B2: East | C2: 1 | D2: 0.9662 | E2: 0.9153 | F2: 0.8027 | G2: 0.641 | H2: 0.4936 | I2: 0.2817
A3: Alabama | B3: East | C3: 2 | D3: 0.946 | E3: 0.7902 | F3: 0.5595 | G3: 0.179 | H3: 0.0848 | I3: 0.0332
A4: Wisconsin | B4: East | C4: 3 | D4: 0.9184 | E4: 0.6027 | F4: 0.2287 | G4: 0.0583 | H4: 0.0248 | I4: 0.0105
A5: Arizona | B5: East | C5: 4 | D5: 0.8519 | E5: 0.5201 | F5: 0.0898 | G5: 0.0394 | H5: 0.0162 | I5: 0.0075
A6: Oregon | B6: East | C6: 5 | D6: 0.7987 | E6: 0.3711 | F6: 0.0533 | G6: 0.0219 | H6: 0.0089 | I6: 0.0042
A7: BYU | B7: East | C7: 6 | D7: 0.6549 | E7: 0.2791 | F7: 0.1121 | G7: 0.0122 | H7: 0.0043 | I7: 0.0022
A8: Saint Mary's | B8: East | C8: 7 | D8: 0.5526 | E8: 0.1222 | F8: 0.037 | G8: 0.0071 | H8: 0.0025 | I8: 0.001
A9: Mississippi State | B9: East | C9: 8 | D9: 0.421 | E9: 0.0214 | F9: 0.0091 | G9: 0.0032 | H9: 0.0013 | I9: 0.0006
A10: Baylor | B10: East | C10: 9 | D10: 0.5472 | E10: 0.0379 | F10: 0.0148 | G10: 0.0067 | H10: 0.0027 | I10: 0.0013
A11: Vanderbilt | B11: East | C11: 10 | D11: 0.4162 | E11: 0.0552 | F11: 0.0199 | G11: 0.0042 | H11: 0.0016 | I11: 0.0007
A12: VCU | B12: East | C12: 11 | D12: 0.3143 | E12: 0.0792 | F12: 0.0153 | G12: 0.0031 | H12: 0.0014 | I12: 0.0006
A13: Liberty | B13: East | C13: 12 | D13: 0.1722 | E13: 0.045 | F13: 0.0057 | G13: 0.0025 | H13: 0.0011 | I13: 0.0005
... A65: Norfolk State | B65: West | C65: 16 | D65: 0.0192 | E65: 0.0081 | F65: 0.004 | G65: 0.0022 | H65: 0.0011 | I65: 0.0006
